22376  2020-04-23 09:22:18,171 INFO create_logger 19 ::: ******************log file created*****************
22376  2020-04-23 09:22:18,171 INFO get_config 14 ::: ******************confReader.py start executing*****************
22376  2020-04-23 09:22:18,173 INFO get_config 31 ::: ************ confReader.py executed successfully ***************
22376  2020-04-23 09:22:18,173 INFO main 1313 ::: config file data :: {'inputdbprop': {'hostname': 'localhost', 'dbname': 'nse', 'dbusername': 'nse', 'dbpassword': 'Happy123'}, 'tablename': 'nsesignals', 'sqlconnection': '../sql/nsesignals.sql', 'requirements': '../lib/requirements.txt'}
22376  2020-04-23 09:22:18,182 INFO db_connet 1241 ::: ******************connected to output table in mysql******************
22376  2020-04-23 09:22:18,184 INFO getSignals 1250 ::: ******************get signal execution started***********************
22376  2020-04-23 09:22:18,184 INFO getSignals 1255 ::: *******************Database connection established********************
22376  2020-04-23 09:23:00,220 INFO getSignals 1259 ::: ****************Required data fetched from database*********************
22376  2020-04-23 09:23:00,328 ERROR getSignals 1306 ::: error ::11 columns passed, passed data had 10 columns
Traceback (most recent call last):
  File "C:\Users\sainikeshk\AppData\Roaming\Python\Python37\site-packages\pandas\core\internals\construction.py", line 497, in _list_to_arrays
    content, columns, dtype=dtype, coerce_float=coerce_float
  File "C:\Users\sainikeshk\AppData\Roaming\Python\Python37\site-packages\pandas\core\internals\construction.py", line 581, in _convert_object_array
    f"{len(columns)} columns passed, passed data had "
AssertionError: 11 columns passed, passed data had 10 columns

The above exception was the direct cause of the following exception:

Traceback (most recent call last):
  File "D:\signals and decisions\bin\getSignals.py", line 1260, in getSignals
    df=pd.DataFrame(list(cur.fetchall()),columns=['symbol', 'series', 'open_adj', 'high_adj', 'low_adj', 'close_adj','prevclose_adj','last_adj', 'tottrdqty_adj', 'tottrdval', 'timestamp'])
  File "C:\Users\sainikeshk\AppData\Roaming\Python\Python37\site-packages\pandas\core\frame.py", line 474, in __init__
    arrays, columns = to_arrays(data, columns, dtype=dtype)
  File "C:\Users\sainikeshk\AppData\Roaming\Python\Python37\site-packages\pandas\core\internals\construction.py", line 461, in to_arrays
    return _list_to_arrays(data, columns, coerce_float=coerce_float, dtype=dtype)
  File "C:\Users\sainikeshk\AppData\Roaming\Python\Python37\site-packages\pandas\core\internals\construction.py", line 500, in _list_to_arrays
    raise ValueError(e) from e
ValueError: 11 columns passed, passed data had 10 columns
