5804  2020-04-22 07:48:32,423 INFO create_logger 19 ::: ******************log file created*****************
5804  2020-04-22 07:48:32,424 INFO get_config 14 ::: ******************confReader.py start executing*****************
5804  2020-04-22 07:48:32,425 INFO get_config 31 ::: ************ confReader.py executed successfully ***************
5804  2020-04-22 07:48:32,425 INFO create_logger 19 ::: ******************log file created*****************
5804  2020-04-22 07:48:32,425 INFO get_config 14 ::: ******************confReader.py start executing*****************
5804  2020-04-22 07:48:32,426 INFO get_config 31 ::: ************ confReader.py executed successfully ***************
5804  2020-04-22 07:48:32,426 INFO main 70 ::: config file data :: {'inputdbprop': {'hostname': 'localhost', 'dbname': 'nse', 'dbusername': 'nse', 'dbpassword': 'Happy123'}, 'tablename': 'nsesignals', 'sqlconnection': '../sql/nsesignals.sql', 'requirements': '../lib/requirements.txt'}
5804  2020-04-22 07:48:32,426 INFO sys_installed_packages 15 ::: ******************packageInstallation.py start executing*****************
5804  2020-04-22 07:48:33,198 INFO sys_installed_packages 26 ::: ******************pip or pip3 is checking already installed packages in system ******************
5804  2020-04-22 07:48:33,198 INFO sys_install_packages 38 ::: ******************collected necessary packages for the smooth execution of the program from requirements.txt file in lib folder******************
5804  2020-04-22 07:48:36,691 INFO sys_install_packages 65 ::: ******************packageInstallation.py completed successfully******************
5804  2020-04-22 07:48:36,691 INFO create_logger 19 ::: ******************log file created*****************
5804  2020-04-22 07:48:36,691 INFO main 55 ::: ******************sqlConnection.py start executing*****************
5804  2020-04-22 07:48:36,691 INFO get_config 14 ::: ******************confReader.py start executing*****************
5804  2020-04-22 07:48:36,692 INFO get_config 31 ::: ************ confReader.py executed successfully ***************
5804  2020-04-22 07:48:36,692 INFO main 58 ::: config file data :: {'inputdbprop': {'hostname': 'localhost', 'dbname': 'nse', 'dbusername': 'nse', 'dbpassword': 'Happy123'}, 'tablename': 'nsesignals', 'sqlconnection': '../sql/nsesignals.sql', 'requirements': '../lib/requirements.txt'}
5804  2020-04-22 07:48:36,713 INFO sqlConnet 15 ::: ******************connected to mysql******************
5804  2020-04-22 07:48:36,735 INFO tableCreation 37 ::: ******************mysql database created***************
5804  2020-04-22 07:48:36,735 INFO tableCreation 38 ::: query == CREATE DATABASE  IF NOT EXISTS `nse`
5804  2020-04-22 07:48:36,751 INFO tableCreation 40 ::: ******************mysql table created******************
5804  2020-04-22 07:48:36,752 INFO tableCreation 41 ::: query == CREATE TABLE IF NOT EXISTS `nsesignals` (`symbol` varchar(16) NOT NULL PRIMARY KEY,`series` varchar(16) NOT NULL,`timestamp` datetime NOT NULL,`money_flow_index` double DEFAULT NULL,`money_flow_index_decisions` varchar(45) DEFAULT NULL,`accumulation_distribution` double DEFAULT NULL,`accumulation_distribution_decisions` varchar(45) DEFAULT NULL,`on_balance_volume` double DEFAULT NULL,`on_balance_volume_decisions` varchar(45) DEFAULT NULL,`ease_of_movement` double DEFAULT NULL,`ease_of_movement_decisions` varchar(45) DEFAULT NULL,`exponential_moving_average` double DEFAULT NULL,`exponential_moving_average_decisions` varchar(45) DEFAULT NULL,`momentum` double DEFAULT NULL,`momentum_decisions` varchar(45) DEFAULT NULL,`chaikin_oscillator` double DEFAULT NULL,`chaikin_oscillator_decisions` varchar(45) DEFAULT NULL,`bollinger_bands_m` double DEFAULT NULL,`bollinger_bands_u` double DEFAULT NULL,`bollinger_bands_d` double DEFAULT NULL,`bollinger_bands_decisions` varchar(45) DEFAULT NULL,`bollinger_bands_per` double DEFAULT NULL,`bollinger_bands_per_decisions` varchar(45) DEFAULT NULL,`williams_ad` double DEFAULT NULL,`williams_ad_decisions` varchar(45) DEFAULT NULL,`williams_r_per` double DEFAULT NULL,`williams_r_per_decisions` varchar(45) DEFAULT NULL,`trix` double DEFAULT NULL,`trix_decisions` varchar(45) DEFAULT NULL,`ultimate_oscillator` double DEFAULT NULL,`ultimate_oscillator_decisions` varchar(45) DEFAULT NULL,`true_strength_index` double DEFAULT NULL,`true_strength_index_decisions` varchar(45) DEFAULT NULL,`force_index` double DEFAULT NULL,`force_index_decisions` varchar(45) DEFAULT NULL,`coppock_curve` double DEFAULT NULL,`coppock_curve_decisions` varchar(45) DEFAULT NULL,`chaikin_money_flow` double DEFAULT NULL,`chaikin_money_flow_decisions` varchar(45) DEFAULT NULL,`keltner_channel_m` double DEFAULT NULL,`keltner_channel_u` double DEFAULT NULL,`keltner_channel_d` double DEFAULT NULL,`keltner_channel_decisions` varchar(45) DEFAULT NULL,`vortex_indicator_plus` double DEFAULT NULL,`vortex_indicator_minus` double DEFAULT NULL,`vortex_indicator_decisions` varchar(45) DEFAULT NULL,`know_sure_thing_oscillator` double DEFAULT NULL,`know_sure_thing_oscillator_decisions` varchar(45) DEFAULT NULL,`rate_of_change` double DEFAULT NULL,`rate_of_change_decisions` varchar(45) DEFAULT NULL,`piv_po` double DEFAULT NULL,`r1` double DEFAULT NULL,`r2` double DEFAULT NULL,`r3` double DEFAULT NULL,`s1` double DEFAULT NULL,`s2` double DEFAULT NULL,`s3` double DEFAULT NULL,`piv_po_decisions` varchar(45) DEFAULT NULL,`stochastic_oscillator_k` double DEFAULT NULL,`stochastic_oscillator_d` double DEFAULT NULL,`stochastic_oscillator_decisions` varchar(45) DEFAULT NULL,`commodity_chan_ind` double DEFAULT NULL,`commodity_chan_ind_decisions` varchar(45) DEFAULT NULL,`awesome_oscillator` double DEFAULT NULL,`awesome_oscillator_decisions` varchar(45) DEFAULT NULL,`detrended_price_oscillator` double DEFAULT NULL,`detrended_price_oscillator_decisions` varchar(45) DEFAULT NULL,`directional_movement_adx` double DEFAULT NULL,`directional_movement_net_di` double DEFAULT NULL,`directional_movement_oscillator_decisions` varchar(45) DEFAULT NULL,`elders_force_index` double DEFAULT NULL,`elders_force_index_decisions` varchar(45) DEFAULT NULL,`upper_envelope` double DEFAULT NULL,`lower_envelope` double DEFAULT NULL,`envelope_decisions` varchar(45) DEFAULT NULL,`acceleration_bands_middle` double DEFAULT NULL,`acceleration_bands_upper` double DEFAULT NULL,`acceleration_bands_lower` double DEFAULT NULL,`acceleration_bands_decisions` varchar(45) DEFAULT NULL,`price_channel_high` double DEFAULT NULL,`price_channel_low` double DEFAULT NULL,`price_channel_center` double DEFAULT NULL,`price_channel_decisions` varchar(45) DEFAULT NULL,`percentage_price_oscillator` double DEFAULT NULL,`percentage_price_oscillator_signal` double DEFAULT NULL,`percentage_price_oscillator_hist` double DEFAULT NULL,`percentage_price_oscillator_decisions` varchar(45) DEFAULT NULL,`price_momentum_oscillator` double DEFAULT NULL,`price_momentum_oscillator_signal` double DEFAULT NULL,`price_momentum_oscillator_decisions` varchar(45) DEFAULT NULL,`ichimoku_lead_span1` double DEFAULT NULL,`ichimoku_lead_span2` double DEFAULT NULL,`ichimoku_lead_decisions` varchar(45) DEFAULT NULL,`macd` double DEFAULT NULL,`macd_signal` double DEFAULT NULL,`macd_decisions` varchar(45) DEFAULT NULL,`relative_strength_index` double DEFAULT NULL,`relative_strength_index_decisions` varchar(45) DEFAULT NULL,`typical_price` double DEFAULT NULL,`typical_price_decisions` varchar(45) DEFAULT NULL,`uptrend_high` double DEFAULT NULL,`uptrend_low` double DEFAULT NULL,`downtrend_low` double DEFAULT NULL,`downtrend_high` double DEFAULT NULL,`trendline_decisions` varchar(45) DEFAULT NULL,`aroon_oscillator` double DEFAULT NULL,`aroon_oscillator_decisions` varchar(45) DEFAULT NULL,`aroon_up` double DEFAULT NULL,`aroon_down` double DEFAULT NULL,`aroon_decisions` varchar(45) DEFAULT NULL,`donchian_channel` double DEFAULT NULL,`donchian_channel_decisions` varchar(45) DEFAULT NULL,`mass_index` double DEFAULT NULL,`calc_ulcer_index` double DEFAULT NULL,`chaikin_volatility` double DEFAULT NULL,`average_true_range` double DEFAULT NULL,`standard_deviation` double DEFAULT NULL,`parabolic_sar_raise` double DEFAULT NULL,`parabolic_sar_fall` double DEFAULT NULL,`volatility` double DEFAULT NULL,`quadrant_range_1` double DEFAULT NULL,`quadrant_range_2` double DEFAULT NULL,`quadrant_range_3` double DEFAULT NULL,`quadrant_range_4` double DEFAULT NULL,`quadrant_range_5` double DEFAULT NULL,`drawdown` double DEFAULT NULL,`heikin_close` double DEFAULT NULL,`heikin_open` double DEFAULT NULL,`heikin_low` double DEFAULT NULL,`heikin_high` double DEFAULT NULL) ENGINE=InnoDB DEFAULT CHARSET=utf8mb4 COLLATE=utf8mb4_0900_ai_ci
5804  2020-04-22 07:48:36,752 INFO tableCreation 47 ::: ******************sqlConnection.py execution completed******************
5804  2020-04-22 07:48:36,752 INFO create_logger 19 ::: ******************log file created*****************
5804  2020-04-22 07:48:36,752 INFO get_config 14 ::: ******************confReader.py start executing*****************
5804  2020-04-22 07:48:36,752 INFO get_config 31 ::: ************ confReader.py executed successfully ***************
5804  2020-04-22 07:48:36,752 INFO main 1315 ::: config file data :: {'inputdbprop': {'hostname': 'localhost', 'dbname': 'nse', 'dbusername': 'nse', 'dbpassword': 'Happy123'}, 'tablename': 'nsesignals', 'sqlconnection': '../sql/nsesignals.sql', 'requirements': '../lib/requirements.txt'}
5804  2020-04-22 07:48:36,755 INFO db_connet 1238 ::: ******************connected to output table in mysql******************
5804  2020-04-22 07:48:36,755 INFO getSignals 1247 ::: ******************get signal execution started***********************
5804  2020-04-22 07:48:36,756 INFO getSignals 1252 ::: *******************Database connection established********************
5804  2020-04-22 07:49:09,568 INFO getSignals 1256 ::: ****************Required data fetched from database*********************
5804  2020-04-22 07:49:10,229 INFO getSignals 1261 ::: *************************Function for signal mining created******************
5804  2020-04-22 07:49:12,296 ERROR getSignals 1287 ::: error ::(1054, "Unknown column '20MICRONS' in 'field list'")
Traceback (most recent call last):
  File "D:\signals and decisions\bin\getSignals.py", line 1285, in getSignals
    cur.execute(isql)
  File "C:\Users\sainikeshk\AppData\Local\Programs\Python\Python37\lib\site-packages\pymysql\cursors.py", line 170, in execute
    result = self._query(query)
  File "C:\Users\sainikeshk\AppData\Local\Programs\Python\Python37\lib\site-packages\pymysql\cursors.py", line 328, in _query
    conn.query(q)
  File "C:\Users\sainikeshk\AppData\Local\Programs\Python\Python37\lib\site-packages\pymysql\connections.py", line 517, in query
    self._affected_rows = self._read_query_result(unbuffered=unbuffered)
  File "C:\Users\sainikeshk\AppData\Local\Programs\Python\Python37\lib\site-packages\pymysql\connections.py", line 732, in _read_query_result
    result.read()
  File "C:\Users\sainikeshk\AppData\Local\Programs\Python\Python37\lib\site-packages\pymysql\connections.py", line 1075, in read
    first_packet = self.connection._read_packet()
  File "C:\Users\sainikeshk\AppData\Local\Programs\Python\Python37\lib\site-packages\pymysql\connections.py", line 684, in _read_packet
    packet.check_error()
  File "C:\Users\sainikeshk\AppData\Local\Programs\Python\Python37\lib\site-packages\pymysql\protocol.py", line 220, in check_error
    err.raise_mysql_exception(self._data)
  File "C:\Users\sainikeshk\AppData\Local\Programs\Python\Python37\lib\site-packages\pymysql\err.py", line 109, in raise_mysql_exception
    raise errorclass(errno, errval)
pymysql.err.InternalError: (1054, "Unknown column '20MICRONS' in 'field list'")
5804  2020-04-22 07:49:14,727 ERROR getSignals 1287 ::: error ::(1054, "Unknown column '3IINFOTECH' in 'field list'")
Traceback (most recent call last):
  File "D:\signals and decisions\bin\getSignals.py", line 1285, in getSignals
    cur.execute(isql)
  File "C:\Users\sainikeshk\AppData\Local\Programs\Python\Python37\lib\site-packages\pymysql\cursors.py", line 170, in execute
    result = self._query(query)
  File "C:\Users\sainikeshk\AppData\Local\Programs\Python\Python37\lib\site-packages\pymysql\cursors.py", line 328, in _query
    conn.query(q)
  File "C:\Users\sainikeshk\AppData\Local\Programs\Python\Python37\lib\site-packages\pymysql\connections.py", line 517, in query
    self._affected_rows = self._read_query_result(unbuffered=unbuffered)
  File "C:\Users\sainikeshk\AppData\Local\Programs\Python\Python37\lib\site-packages\pymysql\connections.py", line 732, in _read_query_result
    result.read()
  File "C:\Users\sainikeshk\AppData\Local\Programs\Python\Python37\lib\site-packages\pymysql\connections.py", line 1075, in read
    first_packet = self.connection._read_packet()
  File "C:\Users\sainikeshk\AppData\Local\Programs\Python\Python37\lib\site-packages\pymysql\connections.py", line 684, in _read_packet
    packet.check_error()
  File "C:\Users\sainikeshk\AppData\Local\Programs\Python\Python37\lib\site-packages\pymysql\protocol.py", line 220, in check_error
    err.raise_mysql_exception(self._data)
  File "C:\Users\sainikeshk\AppData\Local\Programs\Python\Python37\lib\site-packages\pymysql\err.py", line 109, in raise_mysql_exception
    raise errorclass(errno, errval)
pymysql.err.InternalError: (1054, "Unknown column '3IINFOTECH' in 'field list'")
5804  2020-04-22 07:49:16,878 ERROR getSignals 1287 ::: error ::(1054, "Unknown column '3MINDIA' in 'field list'")
Traceback (most recent call last):
  File "D:\signals and decisions\bin\getSignals.py", line 1285, in getSignals
    cur.execute(isql)
  File "C:\Users\sainikeshk\AppData\Local\Programs\Python\Python37\lib\site-packages\pymysql\cursors.py", line 170, in execute
    result = self._query(query)
  File "C:\Users\sainikeshk\AppData\Local\Programs\Python\Python37\lib\site-packages\pymysql\cursors.py", line 328, in _query
    conn.query(q)
  File "C:\Users\sainikeshk\AppData\Local\Programs\Python\Python37\lib\site-packages\pymysql\connections.py", line 517, in query
    self._affected_rows = self._read_query_result(unbuffered=unbuffered)
  File "C:\Users\sainikeshk\AppData\Local\Programs\Python\Python37\lib\site-packages\pymysql\connections.py", line 732, in _read_query_result
    result.read()
  File "C:\Users\sainikeshk\AppData\Local\Programs\Python\Python37\lib\site-packages\pymysql\connections.py", line 1075, in read
    first_packet = self.connection._read_packet()
  File "C:\Users\sainikeshk\AppData\Local\Programs\Python\Python37\lib\site-packages\pymysql\connections.py", line 684, in _read_packet
    packet.check_error()
  File "C:\Users\sainikeshk\AppData\Local\Programs\Python\Python37\lib\site-packages\pymysql\protocol.py", line 220, in check_error
    err.raise_mysql_exception(self._data)
  File "C:\Users\sainikeshk\AppData\Local\Programs\Python\Python37\lib\site-packages\pymysql\err.py", line 109, in raise_mysql_exception
    raise errorclass(errno, errval)
pymysql.err.InternalError: (1054, "Unknown column '3MINDIA' in 'field list'")
5804  2020-04-22 07:49:18,514 ERROR getSignals 1287 ::: error ::(1054, "Unknown column '3PLAND' in 'field list'")
Traceback (most recent call last):
  File "D:\signals and decisions\bin\getSignals.py", line 1285, in getSignals
    cur.execute(isql)
  File "C:\Users\sainikeshk\AppData\Local\Programs\Python\Python37\lib\site-packages\pymysql\cursors.py", line 170, in execute
    result = self._query(query)
  File "C:\Users\sainikeshk\AppData\Local\Programs\Python\Python37\lib\site-packages\pymysql\cursors.py", line 328, in _query
    conn.query(q)
  File "C:\Users\sainikeshk\AppData\Local\Programs\Python\Python37\lib\site-packages\pymysql\connections.py", line 517, in query
    self._affected_rows = self._read_query_result(unbuffered=unbuffered)
  File "C:\Users\sainikeshk\AppData\Local\Programs\Python\Python37\lib\site-packages\pymysql\connections.py", line 732, in _read_query_result
    result.read()
  File "C:\Users\sainikeshk\AppData\Local\Programs\Python\Python37\lib\site-packages\pymysql\connections.py", line 1075, in read
    first_packet = self.connection._read_packet()
  File "C:\Users\sainikeshk\AppData\Local\Programs\Python\Python37\lib\site-packages\pymysql\connections.py", line 684, in _read_packet
    packet.check_error()
  File "C:\Users\sainikeshk\AppData\Local\Programs\Python\Python37\lib\site-packages\pymysql\protocol.py", line 220, in check_error
    err.raise_mysql_exception(self._data)
  File "C:\Users\sainikeshk\AppData\Local\Programs\Python\Python37\lib\site-packages\pymysql\err.py", line 109, in raise_mysql_exception
    raise errorclass(errno, errval)
pymysql.err.InternalError: (1054, "Unknown column '3PLAND' in 'field list'")
5804  2020-04-22 07:49:20,875 ERROR getSignals 1287 ::: error ::(1054, "Unknown column '5PAISA' in 'field list'")
Traceback (most recent call last):
  File "D:\signals and decisions\bin\getSignals.py", line 1285, in getSignals
    cur.execute(isql)
  File "C:\Users\sainikeshk\AppData\Local\Programs\Python\Python37\lib\site-packages\pymysql\cursors.py", line 170, in execute
    result = self._query(query)
  File "C:\Users\sainikeshk\AppData\Local\Programs\Python\Python37\lib\site-packages\pymysql\cursors.py", line 328, in _query
    conn.query(q)
  File "C:\Users\sainikeshk\AppData\Local\Programs\Python\Python37\lib\site-packages\pymysql\connections.py", line 517, in query
    self._affected_rows = self._read_query_result(unbuffered=unbuffered)
  File "C:\Users\sainikeshk\AppData\Local\Programs\Python\Python37\lib\site-packages\pymysql\connections.py", line 732, in _read_query_result
    result.read()
  File "C:\Users\sainikeshk\AppData\Local\Programs\Python\Python37\lib\site-packages\pymysql\connections.py", line 1075, in read
    first_packet = self.connection._read_packet()
  File "C:\Users\sainikeshk\AppData\Local\Programs\Python\Python37\lib\site-packages\pymysql\connections.py", line 684, in _read_packet
    packet.check_error()
  File "C:\Users\sainikeshk\AppData\Local\Programs\Python\Python37\lib\site-packages\pymysql\protocol.py", line 220, in check_error
    err.raise_mysql_exception(self._data)
  File "C:\Users\sainikeshk\AppData\Local\Programs\Python\Python37\lib\site-packages\pymysql\err.py", line 109, in raise_mysql_exception
    raise errorclass(errno, errval)
pymysql.err.InternalError: (1054, "Unknown column '5PAISA' in 'field list'")
5804  2020-04-22 07:49:22,931 ERROR getSignals 1287 ::: error ::(1054, "Unknown column '63MOONS' in 'field list'")
Traceback (most recent call last):
  File "D:\signals and decisions\bin\getSignals.py", line 1285, in getSignals
    cur.execute(isql)
  File "C:\Users\sainikeshk\AppData\Local\Programs\Python\Python37\lib\site-packages\pymysql\cursors.py", line 170, in execute
    result = self._query(query)
  File "C:\Users\sainikeshk\AppData\Local\Programs\Python\Python37\lib\site-packages\pymysql\cursors.py", line 328, in _query
    conn.query(q)
  File "C:\Users\sainikeshk\AppData\Local\Programs\Python\Python37\lib\site-packages\pymysql\connections.py", line 517, in query
    self._affected_rows = self._read_query_result(unbuffered=unbuffered)
  File "C:\Users\sainikeshk\AppData\Local\Programs\Python\Python37\lib\site-packages\pymysql\connections.py", line 732, in _read_query_result
    result.read()
  File "C:\Users\sainikeshk\AppData\Local\Programs\Python\Python37\lib\site-packages\pymysql\connections.py", line 1075, in read
    first_packet = self.connection._read_packet()
  File "C:\Users\sainikeshk\AppData\Local\Programs\Python\Python37\lib\site-packages\pymysql\connections.py", line 684, in _read_packet
    packet.check_error()
  File "C:\Users\sainikeshk\AppData\Local\Programs\Python\Python37\lib\site-packages\pymysql\protocol.py", line 220, in check_error
    err.raise_mysql_exception(self._data)
  File "C:\Users\sainikeshk\AppData\Local\Programs\Python\Python37\lib\site-packages\pymysql\err.py", line 109, in raise_mysql_exception
    raise errorclass(errno, errval)
pymysql.err.InternalError: (1054, "Unknown column '63MOONS' in 'field list'")
5804  2020-04-22 07:49:24,140 ERROR getSignals 1287 ::: error ::(1054, "Unknown column '8KMILES' in 'field list'")
Traceback (most recent call last):
  File "D:\signals and decisions\bin\getSignals.py", line 1285, in getSignals
    cur.execute(isql)
  File "C:\Users\sainikeshk\AppData\Local\Programs\Python\Python37\lib\site-packages\pymysql\cursors.py", line 170, in execute
    result = self._query(query)
  File "C:\Users\sainikeshk\AppData\Local\Programs\Python\Python37\lib\site-packages\pymysql\cursors.py", line 328, in _query
    conn.query(q)
  File "C:\Users\sainikeshk\AppData\Local\Programs\Python\Python37\lib\site-packages\pymysql\connections.py", line 517, in query
    self._affected_rows = self._read_query_result(unbuffered=unbuffered)
  File "C:\Users\sainikeshk\AppData\Local\Programs\Python\Python37\lib\site-packages\pymysql\connections.py", line 732, in _read_query_result
    result.read()
  File "C:\Users\sainikeshk\AppData\Local\Programs\Python\Python37\lib\site-packages\pymysql\connections.py", line 1075, in read
    first_packet = self.connection._read_packet()
  File "C:\Users\sainikeshk\AppData\Local\Programs\Python\Python37\lib\site-packages\pymysql\connections.py", line 684, in _read_packet
    packet.check_error()
  File "C:\Users\sainikeshk\AppData\Local\Programs\Python\Python37\lib\site-packages\pymysql\protocol.py", line 220, in check_error
    err.raise_mysql_exception(self._data)
  File "C:\Users\sainikeshk\AppData\Local\Programs\Python\Python37\lib\site-packages\pymysql\err.py", line 109, in raise_mysql_exception
    raise errorclass(errno, errval)
pymysql.err.InternalError: (1054, "Unknown column '8KMILES' in 'field list'")
5804  2020-04-22 07:49:26,450 ERROR getSignals 1287 ::: error ::(1054, "Unknown column 'A2ZINFRA' in 'field list'")
Traceback (most recent call last):
  File "D:\signals and decisions\bin\getSignals.py", line 1285, in getSignals
    cur.execute(isql)
  File "C:\Users\sainikeshk\AppData\Local\Programs\Python\Python37\lib\site-packages\pymysql\cursors.py", line 170, in execute
    result = self._query(query)
  File "C:\Users\sainikeshk\AppData\Local\Programs\Python\Python37\lib\site-packages\pymysql\cursors.py", line 328, in _query
    conn.query(q)
  File "C:\Users\sainikeshk\AppData\Local\Programs\Python\Python37\lib\site-packages\pymysql\connections.py", line 517, in query
    self._affected_rows = self._read_query_result(unbuffered=unbuffered)
  File "C:\Users\sainikeshk\AppData\Local\Programs\Python\Python37\lib\site-packages\pymysql\connections.py", line 732, in _read_query_result
    result.read()
  File "C:\Users\sainikeshk\AppData\Local\Programs\Python\Python37\lib\site-packages\pymysql\connections.py", line 1075, in read
    first_packet = self.connection._read_packet()
  File "C:\Users\sainikeshk\AppData\Local\Programs\Python\Python37\lib\site-packages\pymysql\connections.py", line 684, in _read_packet
    packet.check_error()
  File "C:\Users\sainikeshk\AppData\Local\Programs\Python\Python37\lib\site-packages\pymysql\protocol.py", line 220, in check_error
    err.raise_mysql_exception(self._data)
  File "C:\Users\sainikeshk\AppData\Local\Programs\Python\Python37\lib\site-packages\pymysql\err.py", line 109, in raise_mysql_exception
    raise errorclass(errno, errval)
pymysql.err.InternalError: (1054, "Unknown column 'A2ZINFRA' in 'field list'")
5804  2020-04-22 07:49:28,529 ERROR getSignals 1287 ::: error ::(1054, "Unknown column 'AARTIDRUGS' in 'field list'")
Traceback (most recent call last):
  File "D:\signals and decisions\bin\getSignals.py", line 1285, in getSignals
    cur.execute(isql)
  File "C:\Users\sainikeshk\AppData\Local\Programs\Python\Python37\lib\site-packages\pymysql\cursors.py", line 170, in execute
    result = self._query(query)
  File "C:\Users\sainikeshk\AppData\Local\Programs\Python\Python37\lib\site-packages\pymysql\cursors.py", line 328, in _query
    conn.query(q)
  File "C:\Users\sainikeshk\AppData\Local\Programs\Python\Python37\lib\site-packages\pymysql\connections.py", line 517, in query
    self._affected_rows = self._read_query_result(unbuffered=unbuffered)
  File "C:\Users\sainikeshk\AppData\Local\Programs\Python\Python37\lib\site-packages\pymysql\connections.py", line 732, in _read_query_result
    result.read()
  File "C:\Users\sainikeshk\AppData\Local\Programs\Python\Python37\lib\site-packages\pymysql\connections.py", line 1075, in read
    first_packet = self.connection._read_packet()
  File "C:\Users\sainikeshk\AppData\Local\Programs\Python\Python37\lib\site-packages\pymysql\connections.py", line 684, in _read_packet
    packet.check_error()
  File "C:\Users\sainikeshk\AppData\Local\Programs\Python\Python37\lib\site-packages\pymysql\protocol.py", line 220, in check_error
    err.raise_mysql_exception(self._data)
  File "C:\Users\sainikeshk\AppData\Local\Programs\Python\Python37\lib\site-packages\pymysql\err.py", line 109, in raise_mysql_exception
    raise errorclass(errno, errval)
pymysql.err.InternalError: (1054, "Unknown column 'AARTIDRUGS' in 'field list'")
5804  2020-04-22 07:49:30,774 ERROR getSignals 1287 ::: error ::(1054, "Unknown column 'AARTIIND' in 'field list'")
Traceback (most recent call last):
  File "D:\signals and decisions\bin\getSignals.py", line 1285, in getSignals
    cur.execute(isql)
  File "C:\Users\sainikeshk\AppData\Local\Programs\Python\Python37\lib\site-packages\pymysql\cursors.py", line 170, in execute
    result = self._query(query)
  File "C:\Users\sainikeshk\AppData\Local\Programs\Python\Python37\lib\site-packages\pymysql\cursors.py", line 328, in _query
    conn.query(q)
  File "C:\Users\sainikeshk\AppData\Local\Programs\Python\Python37\lib\site-packages\pymysql\connections.py", line 517, in query
    self._affected_rows = self._read_query_result(unbuffered=unbuffered)
  File "C:\Users\sainikeshk\AppData\Local\Programs\Python\Python37\lib\site-packages\pymysql\connections.py", line 732, in _read_query_result
    result.read()
  File "C:\Users\sainikeshk\AppData\Local\Programs\Python\Python37\lib\site-packages\pymysql\connections.py", line 1075, in read
    first_packet = self.connection._read_packet()
  File "C:\Users\sainikeshk\AppData\Local\Programs\Python\Python37\lib\site-packages\pymysql\connections.py", line 684, in _read_packet
    packet.check_error()
  File "C:\Users\sainikeshk\AppData\Local\Programs\Python\Python37\lib\site-packages\pymysql\protocol.py", line 220, in check_error
    err.raise_mysql_exception(self._data)
  File "C:\Users\sainikeshk\AppData\Local\Programs\Python\Python37\lib\site-packages\pymysql\err.py", line 109, in raise_mysql_exception
    raise errorclass(errno, errval)
pymysql.err.InternalError: (1054, "Unknown column 'AARTIIND' in 'field list'")
5804  2020-04-22 07:49:32,820 ERROR getSignals 1287 ::: error ::(1054, "Unknown column 'AARVEEDEN' in 'field list'")
Traceback (most recent call last):
  File "D:\signals and decisions\bin\getSignals.py", line 1285, in getSignals
    cur.execute(isql)
  File "C:\Users\sainikeshk\AppData\Local\Programs\Python\Python37\lib\site-packages\pymysql\cursors.py", line 170, in execute
    result = self._query(query)
  File "C:\Users\sainikeshk\AppData\Local\Programs\Python\Python37\lib\site-packages\pymysql\cursors.py", line 328, in _query
    conn.query(q)
  File "C:\Users\sainikeshk\AppData\Local\Programs\Python\Python37\lib\site-packages\pymysql\connections.py", line 517, in query
    self._affected_rows = self._read_query_result(unbuffered=unbuffered)
  File "C:\Users\sainikeshk\AppData\Local\Programs\Python\Python37\lib\site-packages\pymysql\connections.py", line 732, in _read_query_result
    result.read()
  File "C:\Users\sainikeshk\AppData\Local\Programs\Python\Python37\lib\site-packages\pymysql\connections.py", line 1075, in read
    first_packet = self.connection._read_packet()
  File "C:\Users\sainikeshk\AppData\Local\Programs\Python\Python37\lib\site-packages\pymysql\connections.py", line 684, in _read_packet
    packet.check_error()
  File "C:\Users\sainikeshk\AppData\Local\Programs\Python\Python37\lib\site-packages\pymysql\protocol.py", line 220, in check_error
    err.raise_mysql_exception(self._data)
  File "C:\Users\sainikeshk\AppData\Local\Programs\Python\Python37\lib\site-packages\pymysql\err.py", line 109, in raise_mysql_exception
    raise errorclass(errno, errval)
pymysql.err.InternalError: (1054, "Unknown column 'AARVEEDEN' in 'field list'")
5804  2020-04-22 07:49:34,970 ERROR getSignals 1287 ::: error ::(1054, "Unknown column 'AAVAS' in 'field list'")
Traceback (most recent call last):
  File "D:\signals and decisions\bin\getSignals.py", line 1285, in getSignals
    cur.execute(isql)
  File "C:\Users\sainikeshk\AppData\Local\Programs\Python\Python37\lib\site-packages\pymysql\cursors.py", line 170, in execute
    result = self._query(query)
  File "C:\Users\sainikeshk\AppData\Local\Programs\Python\Python37\lib\site-packages\pymysql\cursors.py", line 328, in _query
    conn.query(q)
  File "C:\Users\sainikeshk\AppData\Local\Programs\Python\Python37\lib\site-packages\pymysql\connections.py", line 517, in query
    self._affected_rows = self._read_query_result(unbuffered=unbuffered)
  File "C:\Users\sainikeshk\AppData\Local\Programs\Python\Python37\lib\site-packages\pymysql\connections.py", line 732, in _read_query_result
    result.read()
  File "C:\Users\sainikeshk\AppData\Local\Programs\Python\Python37\lib\site-packages\pymysql\connections.py", line 1075, in read
    first_packet = self.connection._read_packet()
  File "C:\Users\sainikeshk\AppData\Local\Programs\Python\Python37\lib\site-packages\pymysql\connections.py", line 684, in _read_packet
    packet.check_error()
  File "C:\Users\sainikeshk\AppData\Local\Programs\Python\Python37\lib\site-packages\pymysql\protocol.py", line 220, in check_error
    err.raise_mysql_exception(self._data)
  File "C:\Users\sainikeshk\AppData\Local\Programs\Python\Python37\lib\site-packages\pymysql\err.py", line 109, in raise_mysql_exception
    raise errorclass(errno, errval)
pymysql.err.InternalError: (1054, "Unknown column 'AAVAS' in 'field list'")
5804  2020-04-22 07:49:36,730 ERROR getSignals 1287 ::: error ::(1054, "Unknown column 'ABAN' in 'field list'")
Traceback (most recent call last):
  File "D:\signals and decisions\bin\getSignals.py", line 1285, in getSignals
    cur.execute(isql)
  File "C:\Users\sainikeshk\AppData\Local\Programs\Python\Python37\lib\site-packages\pymysql\cursors.py", line 170, in execute
    result = self._query(query)
  File "C:\Users\sainikeshk\AppData\Local\Programs\Python\Python37\lib\site-packages\pymysql\cursors.py", line 328, in _query
    conn.query(q)
  File "C:\Users\sainikeshk\AppData\Local\Programs\Python\Python37\lib\site-packages\pymysql\connections.py", line 517, in query
    self._affected_rows = self._read_query_result(unbuffered=unbuffered)
  File "C:\Users\sainikeshk\AppData\Local\Programs\Python\Python37\lib\site-packages\pymysql\connections.py", line 732, in _read_query_result
    result.read()
  File "C:\Users\sainikeshk\AppData\Local\Programs\Python\Python37\lib\site-packages\pymysql\connections.py", line 1075, in read
    first_packet = self.connection._read_packet()
  File "C:\Users\sainikeshk\AppData\Local\Programs\Python\Python37\lib\site-packages\pymysql\connections.py", line 684, in _read_packet
    packet.check_error()
  File "C:\Users\sainikeshk\AppData\Local\Programs\Python\Python37\lib\site-packages\pymysql\protocol.py", line 220, in check_error
    err.raise_mysql_exception(self._data)
  File "C:\Users\sainikeshk\AppData\Local\Programs\Python\Python37\lib\site-packages\pymysql\err.py", line 109, in raise_mysql_exception
    raise errorclass(errno, errval)
pymysql.err.InternalError: (1054, "Unknown column 'ABAN' in 'field list'")
5804  2020-04-22 07:49:38,793 ERROR getSignals 1287 ::: error ::(1054, "Unknown column 'ABB' in 'field list'")
Traceback (most recent call last):
  File "D:\signals and decisions\bin\getSignals.py", line 1285, in getSignals
    cur.execute(isql)
  File "C:\Users\sainikeshk\AppData\Local\Programs\Python\Python37\lib\site-packages\pymysql\cursors.py", line 170, in execute
    result = self._query(query)
  File "C:\Users\sainikeshk\AppData\Local\Programs\Python\Python37\lib\site-packages\pymysql\cursors.py", line 328, in _query
    conn.query(q)
  File "C:\Users\sainikeshk\AppData\Local\Programs\Python\Python37\lib\site-packages\pymysql\connections.py", line 517, in query
    self._affected_rows = self._read_query_result(unbuffered=unbuffered)
  File "C:\Users\sainikeshk\AppData\Local\Programs\Python\Python37\lib\site-packages\pymysql\connections.py", line 732, in _read_query_result
    result.read()
  File "C:\Users\sainikeshk\AppData\Local\Programs\Python\Python37\lib\site-packages\pymysql\connections.py", line 1075, in read
    first_packet = self.connection._read_packet()
  File "C:\Users\sainikeshk\AppData\Local\Programs\Python\Python37\lib\site-packages\pymysql\connections.py", line 684, in _read_packet
    packet.check_error()
  File "C:\Users\sainikeshk\AppData\Local\Programs\Python\Python37\lib\site-packages\pymysql\protocol.py", line 220, in check_error
    err.raise_mysql_exception(self._data)
  File "C:\Users\sainikeshk\AppData\Local\Programs\Python\Python37\lib\site-packages\pymysql\err.py", line 109, in raise_mysql_exception
    raise errorclass(errno, errval)
pymysql.err.InternalError: (1054, "Unknown column 'ABB' in 'field list'")
5804  2020-04-22 07:49:40,935 ERROR getSignals 1287 ::: error ::(1054, "Unknown column 'ABBOTINDIA' in 'field list'")
Traceback (most recent call last):
  File "D:\signals and decisions\bin\getSignals.py", line 1285, in getSignals
    cur.execute(isql)
  File "C:\Users\sainikeshk\AppData\Local\Programs\Python\Python37\lib\site-packages\pymysql\cursors.py", line 170, in execute
    result = self._query(query)
  File "C:\Users\sainikeshk\AppData\Local\Programs\Python\Python37\lib\site-packages\pymysql\cursors.py", line 328, in _query
    conn.query(q)
  File "C:\Users\sainikeshk\AppData\Local\Programs\Python\Python37\lib\site-packages\pymysql\connections.py", line 517, in query
    self._affected_rows = self._read_query_result(unbuffered=unbuffered)
  File "C:\Users\sainikeshk\AppData\Local\Programs\Python\Python37\lib\site-packages\pymysql\connections.py", line 732, in _read_query_result
    result.read()
  File "C:\Users\sainikeshk\AppData\Local\Programs\Python\Python37\lib\site-packages\pymysql\connections.py", line 1075, in read
    first_packet = self.connection._read_packet()
  File "C:\Users\sainikeshk\AppData\Local\Programs\Python\Python37\lib\site-packages\pymysql\connections.py", line 684, in _read_packet
    packet.check_error()
  File "C:\Users\sainikeshk\AppData\Local\Programs\Python\Python37\lib\site-packages\pymysql\protocol.py", line 220, in check_error
    err.raise_mysql_exception(self._data)
  File "C:\Users\sainikeshk\AppData\Local\Programs\Python\Python37\lib\site-packages\pymysql\err.py", line 109, in raise_mysql_exception
    raise errorclass(errno, errval)
pymysql.err.InternalError: (1054, "Unknown column 'ABBOTINDIA' in 'field list'")
5804  2020-04-22 07:49:43,332 ERROR getSignals 1287 ::: error ::(1054, "Unknown column 'ABCAPITAL' in 'field list'")
Traceback (most recent call last):
  File "D:\signals and decisions\bin\getSignals.py", line 1285, in getSignals
    cur.execute(isql)
  File "C:\Users\sainikeshk\AppData\Local\Programs\Python\Python37\lib\site-packages\pymysql\cursors.py", line 170, in execute
    result = self._query(query)
  File "C:\Users\sainikeshk\AppData\Local\Programs\Python\Python37\lib\site-packages\pymysql\cursors.py", line 328, in _query
    conn.query(q)
  File "C:\Users\sainikeshk\AppData\Local\Programs\Python\Python37\lib\site-packages\pymysql\connections.py", line 517, in query
    self._affected_rows = self._read_query_result(unbuffered=unbuffered)
  File "C:\Users\sainikeshk\AppData\Local\Programs\Python\Python37\lib\site-packages\pymysql\connections.py", line 732, in _read_query_result
    result.read()
  File "C:\Users\sainikeshk\AppData\Local\Programs\Python\Python37\lib\site-packages\pymysql\connections.py", line 1075, in read
    first_packet = self.connection._read_packet()
  File "C:\Users\sainikeshk\AppData\Local\Programs\Python\Python37\lib\site-packages\pymysql\connections.py", line 684, in _read_packet
    packet.check_error()
  File "C:\Users\sainikeshk\AppData\Local\Programs\Python\Python37\lib\site-packages\pymysql\protocol.py", line 220, in check_error
    err.raise_mysql_exception(self._data)
  File "C:\Users\sainikeshk\AppData\Local\Programs\Python\Python37\lib\site-packages\pymysql\err.py", line 109, in raise_mysql_exception
    raise errorclass(errno, errval)
pymysql.err.InternalError: (1054, "Unknown column 'ABCAPITAL' in 'field list'")
5804  2020-04-22 07:49:45,562 ERROR getSignals 1287 ::: error ::(1054, "Unknown column 'ABFRL' in 'field list'")
Traceback (most recent call last):
  File "D:\signals and decisions\bin\getSignals.py", line 1285, in getSignals
    cur.execute(isql)
  File "C:\Users\sainikeshk\AppData\Local\Programs\Python\Python37\lib\site-packages\pymysql\cursors.py", line 170, in execute
    result = self._query(query)
  File "C:\Users\sainikeshk\AppData\Local\Programs\Python\Python37\lib\site-packages\pymysql\cursors.py", line 328, in _query
    conn.query(q)
  File "C:\Users\sainikeshk\AppData\Local\Programs\Python\Python37\lib\site-packages\pymysql\connections.py", line 517, in query
    self._affected_rows = self._read_query_result(unbuffered=unbuffered)
  File "C:\Users\sainikeshk\AppData\Local\Programs\Python\Python37\lib\site-packages\pymysql\connections.py", line 732, in _read_query_result
    result.read()
  File "C:\Users\sainikeshk\AppData\Local\Programs\Python\Python37\lib\site-packages\pymysql\connections.py", line 1075, in read
    first_packet = self.connection._read_packet()
  File "C:\Users\sainikeshk\AppData\Local\Programs\Python\Python37\lib\site-packages\pymysql\connections.py", line 684, in _read_packet
    packet.check_error()
  File "C:\Users\sainikeshk\AppData\Local\Programs\Python\Python37\lib\site-packages\pymysql\protocol.py", line 220, in check_error
    err.raise_mysql_exception(self._data)
  File "C:\Users\sainikeshk\AppData\Local\Programs\Python\Python37\lib\site-packages\pymysql\err.py", line 109, in raise_mysql_exception
    raise errorclass(errno, errval)
pymysql.err.InternalError: (1054, "Unknown column 'ABFRL' in 'field list'")
5804  2020-04-22 07:49:48,169 ERROR getSignals 1287 ::: error ::(1054, "Unknown column 'ACC' in 'field list'")
Traceback (most recent call last):
  File "D:\signals and decisions\bin\getSignals.py", line 1285, in getSignals
    cur.execute(isql)
  File "C:\Users\sainikeshk\AppData\Local\Programs\Python\Python37\lib\site-packages\pymysql\cursors.py", line 170, in execute
    result = self._query(query)
  File "C:\Users\sainikeshk\AppData\Local\Programs\Python\Python37\lib\site-packages\pymysql\cursors.py", line 328, in _query
    conn.query(q)
  File "C:\Users\sainikeshk\AppData\Local\Programs\Python\Python37\lib\site-packages\pymysql\connections.py", line 517, in query
    self._affected_rows = self._read_query_result(unbuffered=unbuffered)
  File "C:\Users\sainikeshk\AppData\Local\Programs\Python\Python37\lib\site-packages\pymysql\connections.py", line 732, in _read_query_result
    result.read()
  File "C:\Users\sainikeshk\AppData\Local\Programs\Python\Python37\lib\site-packages\pymysql\connections.py", line 1075, in read
    first_packet = self.connection._read_packet()
  File "C:\Users\sainikeshk\AppData\Local\Programs\Python\Python37\lib\site-packages\pymysql\connections.py", line 684, in _read_packet
    packet.check_error()
  File "C:\Users\sainikeshk\AppData\Local\Programs\Python\Python37\lib\site-packages\pymysql\protocol.py", line 220, in check_error
    err.raise_mysql_exception(self._data)
  File "C:\Users\sainikeshk\AppData\Local\Programs\Python\Python37\lib\site-packages\pymysql\err.py", line 109, in raise_mysql_exception
    raise errorclass(errno, errval)
pymysql.err.InternalError: (1054, "Unknown column 'ACC' in 'field list'")
5804  2020-04-22 07:49:50,425 ERROR getSignals 1287 ::: error ::(1054, "Unknown column 'ACCELYA' in 'field list'")
Traceback (most recent call last):
  File "D:\signals and decisions\bin\getSignals.py", line 1285, in getSignals
    cur.execute(isql)
  File "C:\Users\sainikeshk\AppData\Local\Programs\Python\Python37\lib\site-packages\pymysql\cursors.py", line 170, in execute
    result = self._query(query)
  File "C:\Users\sainikeshk\AppData\Local\Programs\Python\Python37\lib\site-packages\pymysql\cursors.py", line 328, in _query
    conn.query(q)
  File "C:\Users\sainikeshk\AppData\Local\Programs\Python\Python37\lib\site-packages\pymysql\connections.py", line 517, in query
    self._affected_rows = self._read_query_result(unbuffered=unbuffered)
  File "C:\Users\sainikeshk\AppData\Local\Programs\Python\Python37\lib\site-packages\pymysql\connections.py", line 732, in _read_query_result
    result.read()
  File "C:\Users\sainikeshk\AppData\Local\Programs\Python\Python37\lib\site-packages\pymysql\connections.py", line 1075, in read
    first_packet = self.connection._read_packet()
  File "C:\Users\sainikeshk\AppData\Local\Programs\Python\Python37\lib\site-packages\pymysql\connections.py", line 684, in _read_packet
    packet.check_error()
  File "C:\Users\sainikeshk\AppData\Local\Programs\Python\Python37\lib\site-packages\pymysql\protocol.py", line 220, in check_error
    err.raise_mysql_exception(self._data)
  File "C:\Users\sainikeshk\AppData\Local\Programs\Python\Python37\lib\site-packages\pymysql\err.py", line 109, in raise_mysql_exception
    raise errorclass(errno, errval)
pymysql.err.InternalError: (1054, "Unknown column 'ACCELYA' in 'field list'")
5804  2020-04-22 07:49:52,883 ERROR getSignals 1287 ::: error ::(1054, "Unknown column 'ACE' in 'field list'")
Traceback (most recent call last):
  File "D:\signals and decisions\bin\getSignals.py", line 1285, in getSignals
    cur.execute(isql)
  File "C:\Users\sainikeshk\AppData\Local\Programs\Python\Python37\lib\site-packages\pymysql\cursors.py", line 170, in execute
    result = self._query(query)
  File "C:\Users\sainikeshk\AppData\Local\Programs\Python\Python37\lib\site-packages\pymysql\cursors.py", line 328, in _query
    conn.query(q)
  File "C:\Users\sainikeshk\AppData\Local\Programs\Python\Python37\lib\site-packages\pymysql\connections.py", line 517, in query
    self._affected_rows = self._read_query_result(unbuffered=unbuffered)
  File "C:\Users\sainikeshk\AppData\Local\Programs\Python\Python37\lib\site-packages\pymysql\connections.py", line 732, in _read_query_result
    result.read()
  File "C:\Users\sainikeshk\AppData\Local\Programs\Python\Python37\lib\site-packages\pymysql\connections.py", line 1075, in read
    first_packet = self.connection._read_packet()
  File "C:\Users\sainikeshk\AppData\Local\Programs\Python\Python37\lib\site-packages\pymysql\connections.py", line 684, in _read_packet
    packet.check_error()
  File "C:\Users\sainikeshk\AppData\Local\Programs\Python\Python37\lib\site-packages\pymysql\protocol.py", line 220, in check_error
    err.raise_mysql_exception(self._data)
  File "C:\Users\sainikeshk\AppData\Local\Programs\Python\Python37\lib\site-packages\pymysql\err.py", line 109, in raise_mysql_exception
    raise errorclass(errno, errval)
pymysql.err.InternalError: (1054, "Unknown column 'ACE' in 'field list'")
5804  2020-04-22 07:49:55,051 ERROR getSignals 1287 ::: error ::(1054, "Unknown column 'ADANIENT' in 'field list'")
Traceback (most recent call last):
  File "D:\signals and decisions\bin\getSignals.py", line 1285, in getSignals
    cur.execute(isql)
  File "C:\Users\sainikeshk\AppData\Local\Programs\Python\Python37\lib\site-packages\pymysql\cursors.py", line 170, in execute
    result = self._query(query)
  File "C:\Users\sainikeshk\AppData\Local\Programs\Python\Python37\lib\site-packages\pymysql\cursors.py", line 328, in _query
    conn.query(q)
  File "C:\Users\sainikeshk\AppData\Local\Programs\Python\Python37\lib\site-packages\pymysql\connections.py", line 517, in query
    self._affected_rows = self._read_query_result(unbuffered=unbuffered)
  File "C:\Users\sainikeshk\AppData\Local\Programs\Python\Python37\lib\site-packages\pymysql\connections.py", line 732, in _read_query_result
    result.read()
  File "C:\Users\sainikeshk\AppData\Local\Programs\Python\Python37\lib\site-packages\pymysql\connections.py", line 1075, in read
    first_packet = self.connection._read_packet()
  File "C:\Users\sainikeshk\AppData\Local\Programs\Python\Python37\lib\site-packages\pymysql\connections.py", line 684, in _read_packet
    packet.check_error()
  File "C:\Users\sainikeshk\AppData\Local\Programs\Python\Python37\lib\site-packages\pymysql\protocol.py", line 220, in check_error
    err.raise_mysql_exception(self._data)
  File "C:\Users\sainikeshk\AppData\Local\Programs\Python\Python37\lib\site-packages\pymysql\err.py", line 109, in raise_mysql_exception
    raise errorclass(errno, errval)
pymysql.err.InternalError: (1054, "Unknown column 'ADANIENT' in 'field list'")
5804  2020-04-22 07:49:57,204 ERROR getSignals 1287 ::: error ::(1054, "Unknown column 'ADANIGAS' in 'field list'")
Traceback (most recent call last):
  File "D:\signals and decisions\bin\getSignals.py", line 1285, in getSignals
    cur.execute(isql)
  File "C:\Users\sainikeshk\AppData\Local\Programs\Python\Python37\lib\site-packages\pymysql\cursors.py", line 170, in execute
    result = self._query(query)
  File "C:\Users\sainikeshk\AppData\Local\Programs\Python\Python37\lib\site-packages\pymysql\cursors.py", line 328, in _query
    conn.query(q)
  File "C:\Users\sainikeshk\AppData\Local\Programs\Python\Python37\lib\site-packages\pymysql\connections.py", line 517, in query
    self._affected_rows = self._read_query_result(unbuffered=unbuffered)
  File "C:\Users\sainikeshk\AppData\Local\Programs\Python\Python37\lib\site-packages\pymysql\connections.py", line 732, in _read_query_result
    result.read()
  File "C:\Users\sainikeshk\AppData\Local\Programs\Python\Python37\lib\site-packages\pymysql\connections.py", line 1075, in read
    first_packet = self.connection._read_packet()
  File "C:\Users\sainikeshk\AppData\Local\Programs\Python\Python37\lib\site-packages\pymysql\connections.py", line 684, in _read_packet
    packet.check_error()
  File "C:\Users\sainikeshk\AppData\Local\Programs\Python\Python37\lib\site-packages\pymysql\protocol.py", line 220, in check_error
    err.raise_mysql_exception(self._data)
  File "C:\Users\sainikeshk\AppData\Local\Programs\Python\Python37\lib\site-packages\pymysql\err.py", line 109, in raise_mysql_exception
    raise errorclass(errno, errval)
pymysql.err.InternalError: (1054, "Unknown column 'ADANIGAS' in 'field list'")
5804  2020-04-22 07:49:59,640 ERROR getSignals 1287 ::: error ::(1054, "Unknown column 'ADANIGREEN' in 'field list'")
Traceback (most recent call last):
  File "D:\signals and decisions\bin\getSignals.py", line 1285, in getSignals
    cur.execute(isql)
  File "C:\Users\sainikeshk\AppData\Local\Programs\Python\Python37\lib\site-packages\pymysql\cursors.py", line 170, in execute
    result = self._query(query)
  File "C:\Users\sainikeshk\AppData\Local\Programs\Python\Python37\lib\site-packages\pymysql\cursors.py", line 328, in _query
    conn.query(q)
  File "C:\Users\sainikeshk\AppData\Local\Programs\Python\Python37\lib\site-packages\pymysql\connections.py", line 517, in query
    self._affected_rows = self._read_query_result(unbuffered=unbuffered)
  File "C:\Users\sainikeshk\AppData\Local\Programs\Python\Python37\lib\site-packages\pymysql\connections.py", line 732, in _read_query_result
    result.read()
  File "C:\Users\sainikeshk\AppData\Local\Programs\Python\Python37\lib\site-packages\pymysql\connections.py", line 1075, in read
    first_packet = self.connection._read_packet()
  File "C:\Users\sainikeshk\AppData\Local\Programs\Python\Python37\lib\site-packages\pymysql\connections.py", line 684, in _read_packet
    packet.check_error()
  File "C:\Users\sainikeshk\AppData\Local\Programs\Python\Python37\lib\site-packages\pymysql\protocol.py", line 220, in check_error
    err.raise_mysql_exception(self._data)
  File "C:\Users\sainikeshk\AppData\Local\Programs\Python\Python37\lib\site-packages\pymysql\err.py", line 109, in raise_mysql_exception
    raise errorclass(errno, errval)
pymysql.err.InternalError: (1054, "Unknown column 'ADANIGREEN' in 'field list'")
5804  2020-04-22 07:50:01,743 ERROR getSignals 1287 ::: error ::(1054, "Unknown column 'ADANIPORTS' in 'field list'")
Traceback (most recent call last):
  File "D:\signals and decisions\bin\getSignals.py", line 1285, in getSignals
    cur.execute(isql)
  File "C:\Users\sainikeshk\AppData\Local\Programs\Python\Python37\lib\site-packages\pymysql\cursors.py", line 170, in execute
    result = self._query(query)
  File "C:\Users\sainikeshk\AppData\Local\Programs\Python\Python37\lib\site-packages\pymysql\cursors.py", line 328, in _query
    conn.query(q)
  File "C:\Users\sainikeshk\AppData\Local\Programs\Python\Python37\lib\site-packages\pymysql\connections.py", line 517, in query
    self._affected_rows = self._read_query_result(unbuffered=unbuffered)
  File "C:\Users\sainikeshk\AppData\Local\Programs\Python\Python37\lib\site-packages\pymysql\connections.py", line 732, in _read_query_result
    result.read()
  File "C:\Users\sainikeshk\AppData\Local\Programs\Python\Python37\lib\site-packages\pymysql\connections.py", line 1075, in read
    first_packet = self.connection._read_packet()
  File "C:\Users\sainikeshk\AppData\Local\Programs\Python\Python37\lib\site-packages\pymysql\connections.py", line 684, in _read_packet
    packet.check_error()
  File "C:\Users\sainikeshk\AppData\Local\Programs\Python\Python37\lib\site-packages\pymysql\protocol.py", line 220, in check_error
    err.raise_mysql_exception(self._data)
  File "C:\Users\sainikeshk\AppData\Local\Programs\Python\Python37\lib\site-packages\pymysql\err.py", line 109, in raise_mysql_exception
    raise errorclass(errno, errval)
pymysql.err.InternalError: (1054, "Unknown column 'ADANIPORTS' in 'field list'")
5804  2020-04-22 07:50:04,177 ERROR getSignals 1287 ::: error ::(1054, "Unknown column 'ADANIPOWER' in 'field list'")
Traceback (most recent call last):
  File "D:\signals and decisions\bin\getSignals.py", line 1285, in getSignals
    cur.execute(isql)
  File "C:\Users\sainikeshk\AppData\Local\Programs\Python\Python37\lib\site-packages\pymysql\cursors.py", line 170, in execute
    result = self._query(query)
  File "C:\Users\sainikeshk\AppData\Local\Programs\Python\Python37\lib\site-packages\pymysql\cursors.py", line 328, in _query
    conn.query(q)
  File "C:\Users\sainikeshk\AppData\Local\Programs\Python\Python37\lib\site-packages\pymysql\connections.py", line 517, in query
    self._affected_rows = self._read_query_result(unbuffered=unbuffered)
  File "C:\Users\sainikeshk\AppData\Local\Programs\Python\Python37\lib\site-packages\pymysql\connections.py", line 732, in _read_query_result
    result.read()
  File "C:\Users\sainikeshk\AppData\Local\Programs\Python\Python37\lib\site-packages\pymysql\connections.py", line 1075, in read
    first_packet = self.connection._read_packet()
  File "C:\Users\sainikeshk\AppData\Local\Programs\Python\Python37\lib\site-packages\pymysql\connections.py", line 684, in _read_packet
    packet.check_error()
  File "C:\Users\sainikeshk\AppData\Local\Programs\Python\Python37\lib\site-packages\pymysql\protocol.py", line 220, in check_error
    err.raise_mysql_exception(self._data)
  File "C:\Users\sainikeshk\AppData\Local\Programs\Python\Python37\lib\site-packages\pymysql\err.py", line 109, in raise_mysql_exception
    raise errorclass(errno, errval)
pymysql.err.InternalError: (1054, "Unknown column 'ADANIPOWER' in 'field list'")
5804  2020-04-22 07:50:06,400 ERROR getSignals 1287 ::: error ::(1054, "Unknown column 'ADANITRANS' in 'field list'")
Traceback (most recent call last):
  File "D:\signals and decisions\bin\getSignals.py", line 1285, in getSignals
    cur.execute(isql)
  File "C:\Users\sainikeshk\AppData\Local\Programs\Python\Python37\lib\site-packages\pymysql\cursors.py", line 170, in execute
    result = self._query(query)
  File "C:\Users\sainikeshk\AppData\Local\Programs\Python\Python37\lib\site-packages\pymysql\cursors.py", line 328, in _query
    conn.query(q)
  File "C:\Users\sainikeshk\AppData\Local\Programs\Python\Python37\lib\site-packages\pymysql\connections.py", line 517, in query
    self._affected_rows = self._read_query_result(unbuffered=unbuffered)
  File "C:\Users\sainikeshk\AppData\Local\Programs\Python\Python37\lib\site-packages\pymysql\connections.py", line 732, in _read_query_result
    result.read()
  File "C:\Users\sainikeshk\AppData\Local\Programs\Python\Python37\lib\site-packages\pymysql\connections.py", line 1075, in read
    first_packet = self.connection._read_packet()
  File "C:\Users\sainikeshk\AppData\Local\Programs\Python\Python37\lib\site-packages\pymysql\connections.py", line 684, in _read_packet
    packet.check_error()
  File "C:\Users\sainikeshk\AppData\Local\Programs\Python\Python37\lib\site-packages\pymysql\protocol.py", line 220, in check_error
    err.raise_mysql_exception(self._data)
  File "C:\Users\sainikeshk\AppData\Local\Programs\Python\Python37\lib\site-packages\pymysql\err.py", line 109, in raise_mysql_exception
    raise errorclass(errno, errval)
pymysql.err.InternalError: (1054, "Unknown column 'ADANITRANS' in 'field list'")
5804  2020-04-22 07:50:08,820 ERROR getSignals 1287 ::: error ::(1054, "Unknown column 'ADFFOODS' in 'field list'")
Traceback (most recent call last):
  File "D:\signals and decisions\bin\getSignals.py", line 1285, in getSignals
    cur.execute(isql)
  File "C:\Users\sainikeshk\AppData\Local\Programs\Python\Python37\lib\site-packages\pymysql\cursors.py", line 170, in execute
    result = self._query(query)
  File "C:\Users\sainikeshk\AppData\Local\Programs\Python\Python37\lib\site-packages\pymysql\cursors.py", line 328, in _query
    conn.query(q)
  File "C:\Users\sainikeshk\AppData\Local\Programs\Python\Python37\lib\site-packages\pymysql\connections.py", line 517, in query
    self._affected_rows = self._read_query_result(unbuffered=unbuffered)
  File "C:\Users\sainikeshk\AppData\Local\Programs\Python\Python37\lib\site-packages\pymysql\connections.py", line 732, in _read_query_result
    result.read()
  File "C:\Users\sainikeshk\AppData\Local\Programs\Python\Python37\lib\site-packages\pymysql\connections.py", line 1075, in read
    first_packet = self.connection._read_packet()
  File "C:\Users\sainikeshk\AppData\Local\Programs\Python\Python37\lib\site-packages\pymysql\connections.py", line 684, in _read_packet
    packet.check_error()
  File "C:\Users\sainikeshk\AppData\Local\Programs\Python\Python37\lib\site-packages\pymysql\protocol.py", line 220, in check_error
    err.raise_mysql_exception(self._data)
  File "C:\Users\sainikeshk\AppData\Local\Programs\Python\Python37\lib\site-packages\pymysql\err.py", line 109, in raise_mysql_exception
    raise errorclass(errno, errval)
pymysql.err.InternalError: (1054, "Unknown column 'ADFFOODS' in 'field list'")
5804  2020-04-22 07:50:10,929 ERROR getSignals 1287 ::: error ::(1054, "Unknown column 'ADHUNIKIND' in 'field list'")
Traceback (most recent call last):
  File "D:\signals and decisions\bin\getSignals.py", line 1285, in getSignals
    cur.execute(isql)
  File "C:\Users\sainikeshk\AppData\Local\Programs\Python\Python37\lib\site-packages\pymysql\cursors.py", line 170, in execute
    result = self._query(query)
  File "C:\Users\sainikeshk\AppData\Local\Programs\Python\Python37\lib\site-packages\pymysql\cursors.py", line 328, in _query
    conn.query(q)
  File "C:\Users\sainikeshk\AppData\Local\Programs\Python\Python37\lib\site-packages\pymysql\connections.py", line 517, in query
    self._affected_rows = self._read_query_result(unbuffered=unbuffered)
  File "C:\Users\sainikeshk\AppData\Local\Programs\Python\Python37\lib\site-packages\pymysql\connections.py", line 732, in _read_query_result
    result.read()
  File "C:\Users\sainikeshk\AppData\Local\Programs\Python\Python37\lib\site-packages\pymysql\connections.py", line 1075, in read
    first_packet = self.connection._read_packet()
  File "C:\Users\sainikeshk\AppData\Local\Programs\Python\Python37\lib\site-packages\pymysql\connections.py", line 684, in _read_packet
    packet.check_error()
  File "C:\Users\sainikeshk\AppData\Local\Programs\Python\Python37\lib\site-packages\pymysql\protocol.py", line 220, in check_error
    err.raise_mysql_exception(self._data)
  File "C:\Users\sainikeshk\AppData\Local\Programs\Python\Python37\lib\site-packages\pymysql\err.py", line 109, in raise_mysql_exception
    raise errorclass(errno, errval)
pymysql.err.InternalError: (1054, "Unknown column 'ADHUNIKIND' in 'field list'")
5804  2020-04-22 07:50:12,534 ERROR getSignals 1287 ::: error ::(1054, "Unknown column 'ADLABS' in 'field list'")
Traceback (most recent call last):
  File "D:\signals and decisions\bin\getSignals.py", line 1285, in getSignals
    cur.execute(isql)
  File "C:\Users\sainikeshk\AppData\Local\Programs\Python\Python37\lib\site-packages\pymysql\cursors.py", line 170, in execute
    result = self._query(query)
  File "C:\Users\sainikeshk\AppData\Local\Programs\Python\Python37\lib\site-packages\pymysql\cursors.py", line 328, in _query
    conn.query(q)
  File "C:\Users\sainikeshk\AppData\Local\Programs\Python\Python37\lib\site-packages\pymysql\connections.py", line 517, in query
    self._affected_rows = self._read_query_result(unbuffered=unbuffered)
  File "C:\Users\sainikeshk\AppData\Local\Programs\Python\Python37\lib\site-packages\pymysql\connections.py", line 732, in _read_query_result
    result.read()
  File "C:\Users\sainikeshk\AppData\Local\Programs\Python\Python37\lib\site-packages\pymysql\connections.py", line 1075, in read
    first_packet = self.connection._read_packet()
  File "C:\Users\sainikeshk\AppData\Local\Programs\Python\Python37\lib\site-packages\pymysql\connections.py", line 684, in _read_packet
    packet.check_error()
  File "C:\Users\sainikeshk\AppData\Local\Programs\Python\Python37\lib\site-packages\pymysql\protocol.py", line 220, in check_error
    err.raise_mysql_exception(self._data)
  File "C:\Users\sainikeshk\AppData\Local\Programs\Python\Python37\lib\site-packages\pymysql\err.py", line 109, in raise_mysql_exception
    raise errorclass(errno, errval)
pymysql.err.InternalError: (1054, "Unknown column 'ADLABS' in 'field list'")
5804  2020-04-22 07:50:14,998 ERROR getSignals 1287 ::: error ::(1054, "Unknown column 'ADORWELD' in 'field list'")
Traceback (most recent call last):
  File "D:\signals and decisions\bin\getSignals.py", line 1285, in getSignals
    cur.execute(isql)
  File "C:\Users\sainikeshk\AppData\Local\Programs\Python\Python37\lib\site-packages\pymysql\cursors.py", line 170, in execute
    result = self._query(query)
  File "C:\Users\sainikeshk\AppData\Local\Programs\Python\Python37\lib\site-packages\pymysql\cursors.py", line 328, in _query
    conn.query(q)
  File "C:\Users\sainikeshk\AppData\Local\Programs\Python\Python37\lib\site-packages\pymysql\connections.py", line 517, in query
    self._affected_rows = self._read_query_result(unbuffered=unbuffered)
  File "C:\Users\sainikeshk\AppData\Local\Programs\Python\Python37\lib\site-packages\pymysql\connections.py", line 732, in _read_query_result
    result.read()
  File "C:\Users\sainikeshk\AppData\Local\Programs\Python\Python37\lib\site-packages\pymysql\connections.py", line 1075, in read
    first_packet = self.connection._read_packet()
  File "C:\Users\sainikeshk\AppData\Local\Programs\Python\Python37\lib\site-packages\pymysql\connections.py", line 684, in _read_packet
    packet.check_error()
  File "C:\Users\sainikeshk\AppData\Local\Programs\Python\Python37\lib\site-packages\pymysql\protocol.py", line 220, in check_error
    err.raise_mysql_exception(self._data)
  File "C:\Users\sainikeshk\AppData\Local\Programs\Python\Python37\lib\site-packages\pymysql\err.py", line 109, in raise_mysql_exception
    raise errorclass(errno, errval)
pymysql.err.InternalError: (1054, "Unknown column 'ADORWELD' in 'field list'")
5804  2020-04-22 07:50:15,944 ERROR getSignals 1287 ::: error ::(1054, "Unknown column 'ADROITINFO' in 'field list'")
Traceback (most recent call last):
  File "D:\signals and decisions\bin\getSignals.py", line 1285, in getSignals
    cur.execute(isql)
  File "C:\Users\sainikeshk\AppData\Local\Programs\Python\Python37\lib\site-packages\pymysql\cursors.py", line 170, in execute
    result = self._query(query)
  File "C:\Users\sainikeshk\AppData\Local\Programs\Python\Python37\lib\site-packages\pymysql\cursors.py", line 328, in _query
    conn.query(q)
  File "C:\Users\sainikeshk\AppData\Local\Programs\Python\Python37\lib\site-packages\pymysql\connections.py", line 517, in query
    self._affected_rows = self._read_query_result(unbuffered=unbuffered)
  File "C:\Users\sainikeshk\AppData\Local\Programs\Python\Python37\lib\site-packages\pymysql\connections.py", line 732, in _read_query_result
    result.read()
  File "C:\Users\sainikeshk\AppData\Local\Programs\Python\Python37\lib\site-packages\pymysql\connections.py", line 1075, in read
    first_packet = self.connection._read_packet()
  File "C:\Users\sainikeshk\AppData\Local\Programs\Python\Python37\lib\site-packages\pymysql\connections.py", line 684, in _read_packet
    packet.check_error()
  File "C:\Users\sainikeshk\AppData\Local\Programs\Python\Python37\lib\site-packages\pymysql\protocol.py", line 220, in check_error
    err.raise_mysql_exception(self._data)
  File "C:\Users\sainikeshk\AppData\Local\Programs\Python\Python37\lib\site-packages\pymysql\err.py", line 109, in raise_mysql_exception
    raise errorclass(errno, errval)
pymysql.err.InternalError: (1054, "Unknown column 'ADROITINFO' in 'field list'")
5804  2020-04-22 07:50:17,734 ERROR getSignals 1287 ::: error ::(1054, "Unknown column 'ADSL' in 'field list'")
Traceback (most recent call last):
  File "D:\signals and decisions\bin\getSignals.py", line 1285, in getSignals
    cur.execute(isql)
  File "C:\Users\sainikeshk\AppData\Local\Programs\Python\Python37\lib\site-packages\pymysql\cursors.py", line 170, in execute
    result = self._query(query)
  File "C:\Users\sainikeshk\AppData\Local\Programs\Python\Python37\lib\site-packages\pymysql\cursors.py", line 328, in _query
    conn.query(q)
  File "C:\Users\sainikeshk\AppData\Local\Programs\Python\Python37\lib\site-packages\pymysql\connections.py", line 517, in query
    self._affected_rows = self._read_query_result(unbuffered=unbuffered)
  File "C:\Users\sainikeshk\AppData\Local\Programs\Python\Python37\lib\site-packages\pymysql\connections.py", line 732, in _read_query_result
    result.read()
  File "C:\Users\sainikeshk\AppData\Local\Programs\Python\Python37\lib\site-packages\pymysql\connections.py", line 1075, in read
    first_packet = self.connection._read_packet()
  File "C:\Users\sainikeshk\AppData\Local\Programs\Python\Python37\lib\site-packages\pymysql\connections.py", line 684, in _read_packet
    packet.check_error()
  File "C:\Users\sainikeshk\AppData\Local\Programs\Python\Python37\lib\site-packages\pymysql\protocol.py", line 220, in check_error
    err.raise_mysql_exception(self._data)
  File "C:\Users\sainikeshk\AppData\Local\Programs\Python\Python37\lib\site-packages\pymysql\err.py", line 109, in raise_mysql_exception
    raise errorclass(errno, errval)
pymysql.err.InternalError: (1054, "Unknown column 'ADSL' in 'field list'")
5804  2020-04-22 07:50:20,178 ERROR getSignals 1287 ::: error ::(1054, "Unknown column 'ADVANIHOTR' in 'field list'")
Traceback (most recent call last):
  File "D:\signals and decisions\bin\getSignals.py", line 1285, in getSignals
    cur.execute(isql)
  File "C:\Users\sainikeshk\AppData\Local\Programs\Python\Python37\lib\site-packages\pymysql\cursors.py", line 170, in execute
    result = self._query(query)
  File "C:\Users\sainikeshk\AppData\Local\Programs\Python\Python37\lib\site-packages\pymysql\cursors.py", line 328, in _query
    conn.query(q)
  File "C:\Users\sainikeshk\AppData\Local\Programs\Python\Python37\lib\site-packages\pymysql\connections.py", line 517, in query
    self._affected_rows = self._read_query_result(unbuffered=unbuffered)
  File "C:\Users\sainikeshk\AppData\Local\Programs\Python\Python37\lib\site-packages\pymysql\connections.py", line 732, in _read_query_result
    result.read()
  File "C:\Users\sainikeshk\AppData\Local\Programs\Python\Python37\lib\site-packages\pymysql\connections.py", line 1075, in read
    first_packet = self.connection._read_packet()
  File "C:\Users\sainikeshk\AppData\Local\Programs\Python\Python37\lib\site-packages\pymysql\connections.py", line 684, in _read_packet
    packet.check_error()
  File "C:\Users\sainikeshk\AppData\Local\Programs\Python\Python37\lib\site-packages\pymysql\protocol.py", line 220, in check_error
    err.raise_mysql_exception(self._data)
  File "C:\Users\sainikeshk\AppData\Local\Programs\Python\Python37\lib\site-packages\pymysql\err.py", line 109, in raise_mysql_exception
    raise errorclass(errno, errval)
pymysql.err.InternalError: (1054, "Unknown column 'ADVANIHOTR' in 'field list'")
5804  2020-04-22 07:50:22,337 ERROR getSignals 1287 ::: error ::(1054, "Unknown column 'ADVENZYMES' in 'field list'")
Traceback (most recent call last):
  File "D:\signals and decisions\bin\getSignals.py", line 1285, in getSignals
    cur.execute(isql)
  File "C:\Users\sainikeshk\AppData\Local\Programs\Python\Python37\lib\site-packages\pymysql\cursors.py", line 170, in execute
    result = self._query(query)
  File "C:\Users\sainikeshk\AppData\Local\Programs\Python\Python37\lib\site-packages\pymysql\cursors.py", line 328, in _query
    conn.query(q)
  File "C:\Users\sainikeshk\AppData\Local\Programs\Python\Python37\lib\site-packages\pymysql\connections.py", line 517, in query
    self._affected_rows = self._read_query_result(unbuffered=unbuffered)
  File "C:\Users\sainikeshk\AppData\Local\Programs\Python\Python37\lib\site-packages\pymysql\connections.py", line 732, in _read_query_result
    result.read()
  File "C:\Users\sainikeshk\AppData\Local\Programs\Python\Python37\lib\site-packages\pymysql\connections.py", line 1075, in read
    first_packet = self.connection._read_packet()
  File "C:\Users\sainikeshk\AppData\Local\Programs\Python\Python37\lib\site-packages\pymysql\connections.py", line 684, in _read_packet
    packet.check_error()
  File "C:\Users\sainikeshk\AppData\Local\Programs\Python\Python37\lib\site-packages\pymysql\protocol.py", line 220, in check_error
    err.raise_mysql_exception(self._data)
  File "C:\Users\sainikeshk\AppData\Local\Programs\Python\Python37\lib\site-packages\pymysql\err.py", line 109, in raise_mysql_exception
    raise errorclass(errno, errval)
pymysql.err.InternalError: (1054, "Unknown column 'ADVENZYMES' in 'field list'")
5804  2020-04-22 07:50:24,559 ERROR getSignals 1287 ::: error ::(1054, "Unknown column 'AEGISCHEM' in 'field list'")
Traceback (most recent call last):
  File "D:\signals and decisions\bin\getSignals.py", line 1285, in getSignals
    cur.execute(isql)
  File "C:\Users\sainikeshk\AppData\Local\Programs\Python\Python37\lib\site-packages\pymysql\cursors.py", line 170, in execute
    result = self._query(query)
  File "C:\Users\sainikeshk\AppData\Local\Programs\Python\Python37\lib\site-packages\pymysql\cursors.py", line 328, in _query
    conn.query(q)
  File "C:\Users\sainikeshk\AppData\Local\Programs\Python\Python37\lib\site-packages\pymysql\connections.py", line 517, in query
    self._affected_rows = self._read_query_result(unbuffered=unbuffered)
  File "C:\Users\sainikeshk\AppData\Local\Programs\Python\Python37\lib\site-packages\pymysql\connections.py", line 732, in _read_query_result
    result.read()
  File "C:\Users\sainikeshk\AppData\Local\Programs\Python\Python37\lib\site-packages\pymysql\connections.py", line 1075, in read
    first_packet = self.connection._read_packet()
  File "C:\Users\sainikeshk\AppData\Local\Programs\Python\Python37\lib\site-packages\pymysql\connections.py", line 684, in _read_packet
    packet.check_error()
  File "C:\Users\sainikeshk\AppData\Local\Programs\Python\Python37\lib\site-packages\pymysql\protocol.py", line 220, in check_error
    err.raise_mysql_exception(self._data)
  File "C:\Users\sainikeshk\AppData\Local\Programs\Python\Python37\lib\site-packages\pymysql\err.py", line 109, in raise_mysql_exception
    raise errorclass(errno, errval)
pymysql.err.InternalError: (1054, "Unknown column 'AEGISCHEM' in 'field list'")
5804  2020-04-22 07:50:26,319 ERROR getSignals 1287 ::: error ::(1054, "Unknown column 'AFFLE' in 'field list'")
Traceback (most recent call last):
  File "D:\signals and decisions\bin\getSignals.py", line 1285, in getSignals
    cur.execute(isql)
  File "C:\Users\sainikeshk\AppData\Local\Programs\Python\Python37\lib\site-packages\pymysql\cursors.py", line 170, in execute
    result = self._query(query)
  File "C:\Users\sainikeshk\AppData\Local\Programs\Python\Python37\lib\site-packages\pymysql\cursors.py", line 328, in _query
    conn.query(q)
  File "C:\Users\sainikeshk\AppData\Local\Programs\Python\Python37\lib\site-packages\pymysql\connections.py", line 517, in query
    self._affected_rows = self._read_query_result(unbuffered=unbuffered)
  File "C:\Users\sainikeshk\AppData\Local\Programs\Python\Python37\lib\site-packages\pymysql\connections.py", line 732, in _read_query_result
    result.read()
  File "C:\Users\sainikeshk\AppData\Local\Programs\Python\Python37\lib\site-packages\pymysql\connections.py", line 1075, in read
    first_packet = self.connection._read_packet()
  File "C:\Users\sainikeshk\AppData\Local\Programs\Python\Python37\lib\site-packages\pymysql\connections.py", line 684, in _read_packet
    packet.check_error()
  File "C:\Users\sainikeshk\AppData\Local\Programs\Python\Python37\lib\site-packages\pymysql\protocol.py", line 220, in check_error
    err.raise_mysql_exception(self._data)
  File "C:\Users\sainikeshk\AppData\Local\Programs\Python\Python37\lib\site-packages\pymysql\err.py", line 109, in raise_mysql_exception
    raise errorclass(errno, errval)
pymysql.err.InternalError: (1054, "Unknown column 'AFFLE' in 'field list'")
5804  2020-04-22 07:50:28,440 ERROR getSignals 1287 ::: error ::(1054, "Unknown column 'AGARIND' in 'field list'")
Traceback (most recent call last):
  File "D:\signals and decisions\bin\getSignals.py", line 1285, in getSignals
    cur.execute(isql)
  File "C:\Users\sainikeshk\AppData\Local\Programs\Python\Python37\lib\site-packages\pymysql\cursors.py", line 170, in execute
    result = self._query(query)
  File "C:\Users\sainikeshk\AppData\Local\Programs\Python\Python37\lib\site-packages\pymysql\cursors.py", line 328, in _query
    conn.query(q)
  File "C:\Users\sainikeshk\AppData\Local\Programs\Python\Python37\lib\site-packages\pymysql\connections.py", line 517, in query
    self._affected_rows = self._read_query_result(unbuffered=unbuffered)
  File "C:\Users\sainikeshk\AppData\Local\Programs\Python\Python37\lib\site-packages\pymysql\connections.py", line 732, in _read_query_result
    result.read()
  File "C:\Users\sainikeshk\AppData\Local\Programs\Python\Python37\lib\site-packages\pymysql\connections.py", line 1075, in read
    first_packet = self.connection._read_packet()
  File "C:\Users\sainikeshk\AppData\Local\Programs\Python\Python37\lib\site-packages\pymysql\connections.py", line 684, in _read_packet
    packet.check_error()
  File "C:\Users\sainikeshk\AppData\Local\Programs\Python\Python37\lib\site-packages\pymysql\protocol.py", line 220, in check_error
    err.raise_mysql_exception(self._data)
  File "C:\Users\sainikeshk\AppData\Local\Programs\Python\Python37\lib\site-packages\pymysql\err.py", line 109, in raise_mysql_exception
    raise errorclass(errno, errval)
pymysql.err.InternalError: (1054, "Unknown column 'AGARIND' in 'field list'")
5804  2020-04-22 07:50:29,965 ERROR getSignals 1287 ::: error ::(1054, "Unknown column 'AGCNET' in 'field list'")
Traceback (most recent call last):
  File "D:\signals and decisions\bin\getSignals.py", line 1285, in getSignals
    cur.execute(isql)
  File "C:\Users\sainikeshk\AppData\Local\Programs\Python\Python37\lib\site-packages\pymysql\cursors.py", line 170, in execute
    result = self._query(query)
  File "C:\Users\sainikeshk\AppData\Local\Programs\Python\Python37\lib\site-packages\pymysql\cursors.py", line 328, in _query
    conn.query(q)
  File "C:\Users\sainikeshk\AppData\Local\Programs\Python\Python37\lib\site-packages\pymysql\connections.py", line 517, in query
    self._affected_rows = self._read_query_result(unbuffered=unbuffered)
  File "C:\Users\sainikeshk\AppData\Local\Programs\Python\Python37\lib\site-packages\pymysql\connections.py", line 732, in _read_query_result
    result.read()
  File "C:\Users\sainikeshk\AppData\Local\Programs\Python\Python37\lib\site-packages\pymysql\connections.py", line 1075, in read
    first_packet = self.connection._read_packet()
  File "C:\Users\sainikeshk\AppData\Local\Programs\Python\Python37\lib\site-packages\pymysql\connections.py", line 684, in _read_packet
    packet.check_error()
  File "C:\Users\sainikeshk\AppData\Local\Programs\Python\Python37\lib\site-packages\pymysql\protocol.py", line 220, in check_error
    err.raise_mysql_exception(self._data)
  File "C:\Users\sainikeshk\AppData\Local\Programs\Python\Python37\lib\site-packages\pymysql\err.py", line 109, in raise_mysql_exception
    raise errorclass(errno, errval)
pymysql.err.InternalError: (1054, "Unknown column 'AGCNET' in 'field list'")
5804  2020-04-22 07:50:32,351 ERROR getSignals 1287 ::: error ::(1054, "Unknown column 'AGRITECH' in 'field list'")
Traceback (most recent call last):
  File "D:\signals and decisions\bin\getSignals.py", line 1285, in getSignals
    cur.execute(isql)
  File "C:\Users\sainikeshk\AppData\Local\Programs\Python\Python37\lib\site-packages\pymysql\cursors.py", line 170, in execute
    result = self._query(query)
  File "C:\Users\sainikeshk\AppData\Local\Programs\Python\Python37\lib\site-packages\pymysql\cursors.py", line 328, in _query
    conn.query(q)
  File "C:\Users\sainikeshk\AppData\Local\Programs\Python\Python37\lib\site-packages\pymysql\connections.py", line 517, in query
    self._affected_rows = self._read_query_result(unbuffered=unbuffered)
  File "C:\Users\sainikeshk\AppData\Local\Programs\Python\Python37\lib\site-packages\pymysql\connections.py", line 732, in _read_query_result
    result.read()
  File "C:\Users\sainikeshk\AppData\Local\Programs\Python\Python37\lib\site-packages\pymysql\connections.py", line 1075, in read
    first_packet = self.connection._read_packet()
  File "C:\Users\sainikeshk\AppData\Local\Programs\Python\Python37\lib\site-packages\pymysql\connections.py", line 684, in _read_packet
    packet.check_error()
  File "C:\Users\sainikeshk\AppData\Local\Programs\Python\Python37\lib\site-packages\pymysql\protocol.py", line 220, in check_error
    err.raise_mysql_exception(self._data)
  File "C:\Users\sainikeshk\AppData\Local\Programs\Python\Python37\lib\site-packages\pymysql\err.py", line 109, in raise_mysql_exception
    raise errorclass(errno, errval)
pymysql.err.InternalError: (1054, "Unknown column 'AGRITECH' in 'field list'")
5804  2020-04-22 07:50:33,823 ERROR getSignals 1287 ::: error ::(1054, "Unknown column 'AGROPHOS' in 'field list'")
Traceback (most recent call last):
  File "D:\signals and decisions\bin\getSignals.py", line 1285, in getSignals
    cur.execute(isql)
  File "C:\Users\sainikeshk\AppData\Local\Programs\Python\Python37\lib\site-packages\pymysql\cursors.py", line 170, in execute
    result = self._query(query)
  File "C:\Users\sainikeshk\AppData\Local\Programs\Python\Python37\lib\site-packages\pymysql\cursors.py", line 328, in _query
    conn.query(q)
  File "C:\Users\sainikeshk\AppData\Local\Programs\Python\Python37\lib\site-packages\pymysql\connections.py", line 517, in query
    self._affected_rows = self._read_query_result(unbuffered=unbuffered)
  File "C:\Users\sainikeshk\AppData\Local\Programs\Python\Python37\lib\site-packages\pymysql\connections.py", line 732, in _read_query_result
    result.read()
  File "C:\Users\sainikeshk\AppData\Local\Programs\Python\Python37\lib\site-packages\pymysql\connections.py", line 1075, in read
    first_packet = self.connection._read_packet()
  File "C:\Users\sainikeshk\AppData\Local\Programs\Python\Python37\lib\site-packages\pymysql\connections.py", line 684, in _read_packet
    packet.check_error()
  File "C:\Users\sainikeshk\AppData\Local\Programs\Python\Python37\lib\site-packages\pymysql\protocol.py", line 220, in check_error
    err.raise_mysql_exception(self._data)
  File "C:\Users\sainikeshk\AppData\Local\Programs\Python\Python37\lib\site-packages\pymysql\err.py", line 109, in raise_mysql_exception
    raise errorclass(errno, errval)
pymysql.err.InternalError: (1054, "Unknown column 'AGROPHOS' in 'field list'")
5804  2020-04-22 07:50:36,274 ERROR getSignals 1287 ::: error ::(1054, "Unknown column 'AHLEAST' in 'field list'")
Traceback (most recent call last):
  File "D:\signals and decisions\bin\getSignals.py", line 1285, in getSignals
    cur.execute(isql)
  File "C:\Users\sainikeshk\AppData\Local\Programs\Python\Python37\lib\site-packages\pymysql\cursors.py", line 170, in execute
    result = self._query(query)
  File "C:\Users\sainikeshk\AppData\Local\Programs\Python\Python37\lib\site-packages\pymysql\cursors.py", line 328, in _query
    conn.query(q)
  File "C:\Users\sainikeshk\AppData\Local\Programs\Python\Python37\lib\site-packages\pymysql\connections.py", line 517, in query
    self._affected_rows = self._read_query_result(unbuffered=unbuffered)
  File "C:\Users\sainikeshk\AppData\Local\Programs\Python\Python37\lib\site-packages\pymysql\connections.py", line 732, in _read_query_result
    result.read()
  File "C:\Users\sainikeshk\AppData\Local\Programs\Python\Python37\lib\site-packages\pymysql\connections.py", line 1075, in read
    first_packet = self.connection._read_packet()
  File "C:\Users\sainikeshk\AppData\Local\Programs\Python\Python37\lib\site-packages\pymysql\connections.py", line 684, in _read_packet
    packet.check_error()
  File "C:\Users\sainikeshk\AppData\Local\Programs\Python\Python37\lib\site-packages\pymysql\protocol.py", line 220, in check_error
    err.raise_mysql_exception(self._data)
  File "C:\Users\sainikeshk\AppData\Local\Programs\Python\Python37\lib\site-packages\pymysql\err.py", line 109, in raise_mysql_exception
    raise errorclass(errno, errval)
pymysql.err.InternalError: (1054, "Unknown column 'AHLEAST' in 'field list'")
5804  2020-04-22 07:50:38,491 ERROR getSignals 1287 ::: error ::(1054, "Unknown column 'AHLUCONT' in 'field list'")
Traceback (most recent call last):
  File "D:\signals and decisions\bin\getSignals.py", line 1285, in getSignals
    cur.execute(isql)
  File "C:\Users\sainikeshk\AppData\Local\Programs\Python\Python37\lib\site-packages\pymysql\cursors.py", line 170, in execute
    result = self._query(query)
  File "C:\Users\sainikeshk\AppData\Local\Programs\Python\Python37\lib\site-packages\pymysql\cursors.py", line 328, in _query
    conn.query(q)
  File "C:\Users\sainikeshk\AppData\Local\Programs\Python\Python37\lib\site-packages\pymysql\connections.py", line 517, in query
    self._affected_rows = self._read_query_result(unbuffered=unbuffered)
  File "C:\Users\sainikeshk\AppData\Local\Programs\Python\Python37\lib\site-packages\pymysql\connections.py", line 732, in _read_query_result
    result.read()
  File "C:\Users\sainikeshk\AppData\Local\Programs\Python\Python37\lib\site-packages\pymysql\connections.py", line 1075, in read
    first_packet = self.connection._read_packet()
  File "C:\Users\sainikeshk\AppData\Local\Programs\Python\Python37\lib\site-packages\pymysql\connections.py", line 684, in _read_packet
    packet.check_error()
  File "C:\Users\sainikeshk\AppData\Local\Programs\Python\Python37\lib\site-packages\pymysql\protocol.py", line 220, in check_error
    err.raise_mysql_exception(self._data)
  File "C:\Users\sainikeshk\AppData\Local\Programs\Python\Python37\lib\site-packages\pymysql\err.py", line 109, in raise_mysql_exception
    raise errorclass(errno, errval)
pymysql.err.InternalError: (1054, "Unknown column 'AHLUCONT' in 'field list'")
5804  2020-04-22 07:50:40,533 ERROR getSignals 1287 ::: error ::(1054, "Unknown column 'AHLWEST' in 'field list'")
Traceback (most recent call last):
  File "D:\signals and decisions\bin\getSignals.py", line 1285, in getSignals
    cur.execute(isql)
  File "C:\Users\sainikeshk\AppData\Local\Programs\Python\Python37\lib\site-packages\pymysql\cursors.py", line 170, in execute
    result = self._query(query)
  File "C:\Users\sainikeshk\AppData\Local\Programs\Python\Python37\lib\site-packages\pymysql\cursors.py", line 328, in _query
    conn.query(q)
  File "C:\Users\sainikeshk\AppData\Local\Programs\Python\Python37\lib\site-packages\pymysql\connections.py", line 517, in query
    self._affected_rows = self._read_query_result(unbuffered=unbuffered)
  File "C:\Users\sainikeshk\AppData\Local\Programs\Python\Python37\lib\site-packages\pymysql\connections.py", line 732, in _read_query_result
    result.read()
  File "C:\Users\sainikeshk\AppData\Local\Programs\Python\Python37\lib\site-packages\pymysql\connections.py", line 1075, in read
    first_packet = self.connection._read_packet()
  File "C:\Users\sainikeshk\AppData\Local\Programs\Python\Python37\lib\site-packages\pymysql\connections.py", line 684, in _read_packet
    packet.check_error()
  File "C:\Users\sainikeshk\AppData\Local\Programs\Python\Python37\lib\site-packages\pymysql\protocol.py", line 220, in check_error
    err.raise_mysql_exception(self._data)
  File "C:\Users\sainikeshk\AppData\Local\Programs\Python\Python37\lib\site-packages\pymysql\err.py", line 109, in raise_mysql_exception
    raise errorclass(errno, errval)
pymysql.err.InternalError: (1054, "Unknown column 'AHLWEST' in 'field list'")
5804  2020-04-22 07:50:42,983 ERROR getSignals 1287 ::: error ::(1054, "Unknown column 'AIAENG' in 'field list'")
Traceback (most recent call last):
  File "D:\signals and decisions\bin\getSignals.py", line 1285, in getSignals
    cur.execute(isql)
  File "C:\Users\sainikeshk\AppData\Local\Programs\Python\Python37\lib\site-packages\pymysql\cursors.py", line 170, in execute
    result = self._query(query)
  File "C:\Users\sainikeshk\AppData\Local\Programs\Python\Python37\lib\site-packages\pymysql\cursors.py", line 328, in _query
    conn.query(q)
  File "C:\Users\sainikeshk\AppData\Local\Programs\Python\Python37\lib\site-packages\pymysql\connections.py", line 517, in query
    self._affected_rows = self._read_query_result(unbuffered=unbuffered)
  File "C:\Users\sainikeshk\AppData\Local\Programs\Python\Python37\lib\site-packages\pymysql\connections.py", line 732, in _read_query_result
    result.read()
  File "C:\Users\sainikeshk\AppData\Local\Programs\Python\Python37\lib\site-packages\pymysql\connections.py", line 1075, in read
    first_packet = self.connection._read_packet()
  File "C:\Users\sainikeshk\AppData\Local\Programs\Python\Python37\lib\site-packages\pymysql\connections.py", line 684, in _read_packet
    packet.check_error()
  File "C:\Users\sainikeshk\AppData\Local\Programs\Python\Python37\lib\site-packages\pymysql\protocol.py", line 220, in check_error
    err.raise_mysql_exception(self._data)
  File "C:\Users\sainikeshk\AppData\Local\Programs\Python\Python37\lib\site-packages\pymysql\err.py", line 109, in raise_mysql_exception
    raise errorclass(errno, errval)
pymysql.err.InternalError: (1054, "Unknown column 'AIAENG' in 'field list'")
5804  2020-04-22 07:50:45,126 ERROR getSignals 1287 ::: error ::(1054, "Unknown column 'AIONJSW' in 'field list'")
Traceback (most recent call last):
  File "D:\signals and decisions\bin\getSignals.py", line 1285, in getSignals
    cur.execute(isql)
  File "C:\Users\sainikeshk\AppData\Local\Programs\Python\Python37\lib\site-packages\pymysql\cursors.py", line 170, in execute
    result = self._query(query)
  File "C:\Users\sainikeshk\AppData\Local\Programs\Python\Python37\lib\site-packages\pymysql\cursors.py", line 328, in _query
    conn.query(q)
  File "C:\Users\sainikeshk\AppData\Local\Programs\Python\Python37\lib\site-packages\pymysql\connections.py", line 517, in query
    self._affected_rows = self._read_query_result(unbuffered=unbuffered)
  File "C:\Users\sainikeshk\AppData\Local\Programs\Python\Python37\lib\site-packages\pymysql\connections.py", line 732, in _read_query_result
    result.read()
  File "C:\Users\sainikeshk\AppData\Local\Programs\Python\Python37\lib\site-packages\pymysql\connections.py", line 1075, in read
    first_packet = self.connection._read_packet()
  File "C:\Users\sainikeshk\AppData\Local\Programs\Python\Python37\lib\site-packages\pymysql\connections.py", line 684, in _read_packet
    packet.check_error()
  File "C:\Users\sainikeshk\AppData\Local\Programs\Python\Python37\lib\site-packages\pymysql\protocol.py", line 220, in check_error
    err.raise_mysql_exception(self._data)
  File "C:\Users\sainikeshk\AppData\Local\Programs\Python\Python37\lib\site-packages\pymysql\err.py", line 109, in raise_mysql_exception
    raise errorclass(errno, errval)
pymysql.err.InternalError: (1054, "Unknown column 'AIONJSW' in 'field list'")
5804  2020-04-22 07:50:47,482 ERROR getSignals 1287 ::: error ::(1054, "Unknown column 'AIRAN' in 'field list'")
Traceback (most recent call last):
  File "D:\signals and decisions\bin\getSignals.py", line 1285, in getSignals
    cur.execute(isql)
  File "C:\Users\sainikeshk\AppData\Local\Programs\Python\Python37\lib\site-packages\pymysql\cursors.py", line 170, in execute
    result = self._query(query)
  File "C:\Users\sainikeshk\AppData\Local\Programs\Python\Python37\lib\site-packages\pymysql\cursors.py", line 328, in _query
    conn.query(q)
  File "C:\Users\sainikeshk\AppData\Local\Programs\Python\Python37\lib\site-packages\pymysql\connections.py", line 517, in query
    self._affected_rows = self._read_query_result(unbuffered=unbuffered)
  File "C:\Users\sainikeshk\AppData\Local\Programs\Python\Python37\lib\site-packages\pymysql\connections.py", line 732, in _read_query_result
    result.read()
  File "C:\Users\sainikeshk\AppData\Local\Programs\Python\Python37\lib\site-packages\pymysql\connections.py", line 1075, in read
    first_packet = self.connection._read_packet()
  File "C:\Users\sainikeshk\AppData\Local\Programs\Python\Python37\lib\site-packages\pymysql\connections.py", line 684, in _read_packet
    packet.check_error()
  File "C:\Users\sainikeshk\AppData\Local\Programs\Python\Python37\lib\site-packages\pymysql\protocol.py", line 220, in check_error
    err.raise_mysql_exception(self._data)
  File "C:\Users\sainikeshk\AppData\Local\Programs\Python\Python37\lib\site-packages\pymysql\err.py", line 109, in raise_mysql_exception
    raise errorclass(errno, errval)
pymysql.err.InternalError: (1054, "Unknown column 'AIRAN' in 'field list'")
5804  2020-04-22 07:50:49,644 ERROR getSignals 1287 ::: error ::(1054, "Unknown column 'AJANTPHARM' in 'field list'")
Traceback (most recent call last):
  File "D:\signals and decisions\bin\getSignals.py", line 1285, in getSignals
    cur.execute(isql)
  File "C:\Users\sainikeshk\AppData\Local\Programs\Python\Python37\lib\site-packages\pymysql\cursors.py", line 170, in execute
    result = self._query(query)
  File "C:\Users\sainikeshk\AppData\Local\Programs\Python\Python37\lib\site-packages\pymysql\cursors.py", line 328, in _query
    conn.query(q)
  File "C:\Users\sainikeshk\AppData\Local\Programs\Python\Python37\lib\site-packages\pymysql\connections.py", line 517, in query
    self._affected_rows = self._read_query_result(unbuffered=unbuffered)
  File "C:\Users\sainikeshk\AppData\Local\Programs\Python\Python37\lib\site-packages\pymysql\connections.py", line 732, in _read_query_result
    result.read()
  File "C:\Users\sainikeshk\AppData\Local\Programs\Python\Python37\lib\site-packages\pymysql\connections.py", line 1075, in read
    first_packet = self.connection._read_packet()
  File "C:\Users\sainikeshk\AppData\Local\Programs\Python\Python37\lib\site-packages\pymysql\connections.py", line 684, in _read_packet
    packet.check_error()
  File "C:\Users\sainikeshk\AppData\Local\Programs\Python\Python37\lib\site-packages\pymysql\protocol.py", line 220, in check_error
    err.raise_mysql_exception(self._data)
  File "C:\Users\sainikeshk\AppData\Local\Programs\Python\Python37\lib\site-packages\pymysql\err.py", line 109, in raise_mysql_exception
    raise errorclass(errno, errval)
pymysql.err.InternalError: (1054, "Unknown column 'AJANTPHARM' in 'field list'")
5804  2020-04-22 07:50:51,771 ERROR getSignals 1287 ::: error ::(1054, "Unknown column 'AJMERA' in 'field list'")
Traceback (most recent call last):
  File "D:\signals and decisions\bin\getSignals.py", line 1285, in getSignals
    cur.execute(isql)
  File "C:\Users\sainikeshk\AppData\Local\Programs\Python\Python37\lib\site-packages\pymysql\cursors.py", line 170, in execute
    result = self._query(query)
  File "C:\Users\sainikeshk\AppData\Local\Programs\Python\Python37\lib\site-packages\pymysql\cursors.py", line 328, in _query
    conn.query(q)
  File "C:\Users\sainikeshk\AppData\Local\Programs\Python\Python37\lib\site-packages\pymysql\connections.py", line 517, in query
    self._affected_rows = self._read_query_result(unbuffered=unbuffered)
  File "C:\Users\sainikeshk\AppData\Local\Programs\Python\Python37\lib\site-packages\pymysql\connections.py", line 732, in _read_query_result
    result.read()
  File "C:\Users\sainikeshk\AppData\Local\Programs\Python\Python37\lib\site-packages\pymysql\connections.py", line 1075, in read
    first_packet = self.connection._read_packet()
  File "C:\Users\sainikeshk\AppData\Local\Programs\Python\Python37\lib\site-packages\pymysql\connections.py", line 684, in _read_packet
    packet.check_error()
  File "C:\Users\sainikeshk\AppData\Local\Programs\Python\Python37\lib\site-packages\pymysql\protocol.py", line 220, in check_error
    err.raise_mysql_exception(self._data)
  File "C:\Users\sainikeshk\AppData\Local\Programs\Python\Python37\lib\site-packages\pymysql\err.py", line 109, in raise_mysql_exception
    raise errorclass(errno, errval)
pymysql.err.InternalError: (1054, "Unknown column 'AJMERA' in 'field list'")
5804  2020-04-22 07:50:53,008 ERROR getSignals 1287 ::: error ::(1054, "Unknown column 'AKASH' in 'field list'")
Traceback (most recent call last):
  File "D:\signals and decisions\bin\getSignals.py", line 1285, in getSignals
    cur.execute(isql)
  File "C:\Users\sainikeshk\AppData\Local\Programs\Python\Python37\lib\site-packages\pymysql\cursors.py", line 170, in execute
    result = self._query(query)
  File "C:\Users\sainikeshk\AppData\Local\Programs\Python\Python37\lib\site-packages\pymysql\cursors.py", line 328, in _query
    conn.query(q)
  File "C:\Users\sainikeshk\AppData\Local\Programs\Python\Python37\lib\site-packages\pymysql\connections.py", line 517, in query
    self._affected_rows = self._read_query_result(unbuffered=unbuffered)
  File "C:\Users\sainikeshk\AppData\Local\Programs\Python\Python37\lib\site-packages\pymysql\connections.py", line 732, in _read_query_result
    result.read()
  File "C:\Users\sainikeshk\AppData\Local\Programs\Python\Python37\lib\site-packages\pymysql\connections.py", line 1075, in read
    first_packet = self.connection._read_packet()
  File "C:\Users\sainikeshk\AppData\Local\Programs\Python\Python37\lib\site-packages\pymysql\connections.py", line 684, in _read_packet
    packet.check_error()
  File "C:\Users\sainikeshk\AppData\Local\Programs\Python\Python37\lib\site-packages\pymysql\protocol.py", line 220, in check_error
    err.raise_mysql_exception(self._data)
  File "C:\Users\sainikeshk\AppData\Local\Programs\Python\Python37\lib\site-packages\pymysql\err.py", line 109, in raise_mysql_exception
    raise errorclass(errno, errval)
pymysql.err.InternalError: (1054, "Unknown column 'AKASH' in 'field list'")
5804  2020-04-22 07:50:55,270 ERROR getSignals 1287 ::: error ::(1054, "Unknown column 'AKSHARCHEM' in 'field list'")
Traceback (most recent call last):
  File "D:\signals and decisions\bin\getSignals.py", line 1285, in getSignals
    cur.execute(isql)
  File "C:\Users\sainikeshk\AppData\Local\Programs\Python\Python37\lib\site-packages\pymysql\cursors.py", line 170, in execute
    result = self._query(query)
  File "C:\Users\sainikeshk\AppData\Local\Programs\Python\Python37\lib\site-packages\pymysql\cursors.py", line 328, in _query
    conn.query(q)
  File "C:\Users\sainikeshk\AppData\Local\Programs\Python\Python37\lib\site-packages\pymysql\connections.py", line 517, in query
    self._affected_rows = self._read_query_result(unbuffered=unbuffered)
  File "C:\Users\sainikeshk\AppData\Local\Programs\Python\Python37\lib\site-packages\pymysql\connections.py", line 732, in _read_query_result
    result.read()
  File "C:\Users\sainikeshk\AppData\Local\Programs\Python\Python37\lib\site-packages\pymysql\connections.py", line 1075, in read
    first_packet = self.connection._read_packet()
  File "C:\Users\sainikeshk\AppData\Local\Programs\Python\Python37\lib\site-packages\pymysql\connections.py", line 684, in _read_packet
    packet.check_error()
  File "C:\Users\sainikeshk\AppData\Local\Programs\Python\Python37\lib\site-packages\pymysql\protocol.py", line 220, in check_error
    err.raise_mysql_exception(self._data)
  File "C:\Users\sainikeshk\AppData\Local\Programs\Python\Python37\lib\site-packages\pymysql\err.py", line 109, in raise_mysql_exception
    raise errorclass(errno, errval)
pymysql.err.InternalError: (1054, "Unknown column 'AKSHARCHEM' in 'field list'")
5804  2020-04-22 07:50:57,589 ERROR getSignals 1287 ::: error ::(1054, "Unknown column 'AKSHOPTFBR' in 'field list'")
Traceback (most recent call last):
  File "D:\signals and decisions\bin\getSignals.py", line 1285, in getSignals
    cur.execute(isql)
  File "C:\Users\sainikeshk\AppData\Local\Programs\Python\Python37\lib\site-packages\pymysql\cursors.py", line 170, in execute
    result = self._query(query)
  File "C:\Users\sainikeshk\AppData\Local\Programs\Python\Python37\lib\site-packages\pymysql\cursors.py", line 328, in _query
    conn.query(q)
  File "C:\Users\sainikeshk\AppData\Local\Programs\Python\Python37\lib\site-packages\pymysql\connections.py", line 517, in query
    self._affected_rows = self._read_query_result(unbuffered=unbuffered)
  File "C:\Users\sainikeshk\AppData\Local\Programs\Python\Python37\lib\site-packages\pymysql\connections.py", line 732, in _read_query_result
    result.read()
  File "C:\Users\sainikeshk\AppData\Local\Programs\Python\Python37\lib\site-packages\pymysql\connections.py", line 1075, in read
    first_packet = self.connection._read_packet()
  File "C:\Users\sainikeshk\AppData\Local\Programs\Python\Python37\lib\site-packages\pymysql\connections.py", line 684, in _read_packet
    packet.check_error()
  File "C:\Users\sainikeshk\AppData\Local\Programs\Python\Python37\lib\site-packages\pymysql\protocol.py", line 220, in check_error
    err.raise_mysql_exception(self._data)
  File "C:\Users\sainikeshk\AppData\Local\Programs\Python\Python37\lib\site-packages\pymysql\err.py", line 109, in raise_mysql_exception
    raise errorclass(errno, errval)
pymysql.err.InternalError: (1054, "Unknown column 'AKSHOPTFBR' in 'field list'")
5804  2020-04-22 07:50:59,705 ERROR getSignals 1287 ::: error ::(1054, "Unknown column 'AKZOINDIA' in 'field list'")
Traceback (most recent call last):
  File "D:\signals and decisions\bin\getSignals.py", line 1285, in getSignals
    cur.execute(isql)
  File "C:\Users\sainikeshk\AppData\Local\Programs\Python\Python37\lib\site-packages\pymysql\cursors.py", line 170, in execute
    result = self._query(query)
  File "C:\Users\sainikeshk\AppData\Local\Programs\Python\Python37\lib\site-packages\pymysql\cursors.py", line 328, in _query
    conn.query(q)
  File "C:\Users\sainikeshk\AppData\Local\Programs\Python\Python37\lib\site-packages\pymysql\connections.py", line 517, in query
    self._affected_rows = self._read_query_result(unbuffered=unbuffered)
  File "C:\Users\sainikeshk\AppData\Local\Programs\Python\Python37\lib\site-packages\pymysql\connections.py", line 732, in _read_query_result
    result.read()
  File "C:\Users\sainikeshk\AppData\Local\Programs\Python\Python37\lib\site-packages\pymysql\connections.py", line 1075, in read
    first_packet = self.connection._read_packet()
  File "C:\Users\sainikeshk\AppData\Local\Programs\Python\Python37\lib\site-packages\pymysql\connections.py", line 684, in _read_packet
    packet.check_error()
  File "C:\Users\sainikeshk\AppData\Local\Programs\Python\Python37\lib\site-packages\pymysql\protocol.py", line 220, in check_error
    err.raise_mysql_exception(self._data)
  File "C:\Users\sainikeshk\AppData\Local\Programs\Python\Python37\lib\site-packages\pymysql\err.py", line 109, in raise_mysql_exception
    raise errorclass(errno, errval)
pymysql.err.InternalError: (1054, "Unknown column 'AKZOINDIA' in 'field list'")
5804  2020-04-22 07:51:01,819 ERROR getSignals 1287 ::: error ::(1054, "Unknown column 'ALANKIT' in 'field list'")
Traceback (most recent call last):
  File "D:\signals and decisions\bin\getSignals.py", line 1285, in getSignals
    cur.execute(isql)
  File "C:\Users\sainikeshk\AppData\Local\Programs\Python\Python37\lib\site-packages\pymysql\cursors.py", line 170, in execute
    result = self._query(query)
  File "C:\Users\sainikeshk\AppData\Local\Programs\Python\Python37\lib\site-packages\pymysql\cursors.py", line 328, in _query
    conn.query(q)
  File "C:\Users\sainikeshk\AppData\Local\Programs\Python\Python37\lib\site-packages\pymysql\connections.py", line 517, in query
    self._affected_rows = self._read_query_result(unbuffered=unbuffered)
  File "C:\Users\sainikeshk\AppData\Local\Programs\Python\Python37\lib\site-packages\pymysql\connections.py", line 732, in _read_query_result
    result.read()
  File "C:\Users\sainikeshk\AppData\Local\Programs\Python\Python37\lib\site-packages\pymysql\connections.py", line 1075, in read
    first_packet = self.connection._read_packet()
  File "C:\Users\sainikeshk\AppData\Local\Programs\Python\Python37\lib\site-packages\pymysql\connections.py", line 684, in _read_packet
    packet.check_error()
  File "C:\Users\sainikeshk\AppData\Local\Programs\Python\Python37\lib\site-packages\pymysql\protocol.py", line 220, in check_error
    err.raise_mysql_exception(self._data)
  File "C:\Users\sainikeshk\AppData\Local\Programs\Python\Python37\lib\site-packages\pymysql\err.py", line 109, in raise_mysql_exception
    raise errorclass(errno, errval)
pymysql.err.InternalError: (1054, "Unknown column 'ALANKIT' in 'field list'")
5804  2020-04-22 07:51:04,146 ERROR getSignals 1287 ::: error ::(1054, "Unknown column 'ALBERTDAVD' in 'field list'")
Traceback (most recent call last):
  File "D:\signals and decisions\bin\getSignals.py", line 1285, in getSignals
    cur.execute(isql)
  File "C:\Users\sainikeshk\AppData\Local\Programs\Python\Python37\lib\site-packages\pymysql\cursors.py", line 170, in execute
    result = self._query(query)
  File "C:\Users\sainikeshk\AppData\Local\Programs\Python\Python37\lib\site-packages\pymysql\cursors.py", line 328, in _query
    conn.query(q)
  File "C:\Users\sainikeshk\AppData\Local\Programs\Python\Python37\lib\site-packages\pymysql\connections.py", line 517, in query
    self._affected_rows = self._read_query_result(unbuffered=unbuffered)
  File "C:\Users\sainikeshk\AppData\Local\Programs\Python\Python37\lib\site-packages\pymysql\connections.py", line 732, in _read_query_result
    result.read()
  File "C:\Users\sainikeshk\AppData\Local\Programs\Python\Python37\lib\site-packages\pymysql\connections.py", line 1075, in read
    first_packet = self.connection._read_packet()
  File "C:\Users\sainikeshk\AppData\Local\Programs\Python\Python37\lib\site-packages\pymysql\connections.py", line 684, in _read_packet
    packet.check_error()
  File "C:\Users\sainikeshk\AppData\Local\Programs\Python\Python37\lib\site-packages\pymysql\protocol.py", line 220, in check_error
    err.raise_mysql_exception(self._data)
  File "C:\Users\sainikeshk\AppData\Local\Programs\Python\Python37\lib\site-packages\pymysql\err.py", line 109, in raise_mysql_exception
    raise errorclass(errno, errval)
pymysql.err.InternalError: (1054, "Unknown column 'ALBERTDAVD' in 'field list'")
5804  2020-04-22 07:51:06,095 ERROR getSignals 1287 ::: error ::(1054, "Unknown column 'ALBK' in 'field list'")
Traceback (most recent call last):
  File "D:\signals and decisions\bin\getSignals.py", line 1285, in getSignals
    cur.execute(isql)
  File "C:\Users\sainikeshk\AppData\Local\Programs\Python\Python37\lib\site-packages\pymysql\cursors.py", line 170, in execute
    result = self._query(query)
  File "C:\Users\sainikeshk\AppData\Local\Programs\Python\Python37\lib\site-packages\pymysql\cursors.py", line 328, in _query
    conn.query(q)
  File "C:\Users\sainikeshk\AppData\Local\Programs\Python\Python37\lib\site-packages\pymysql\connections.py", line 517, in query
    self._affected_rows = self._read_query_result(unbuffered=unbuffered)
  File "C:\Users\sainikeshk\AppData\Local\Programs\Python\Python37\lib\site-packages\pymysql\connections.py", line 732, in _read_query_result
    result.read()
  File "C:\Users\sainikeshk\AppData\Local\Programs\Python\Python37\lib\site-packages\pymysql\connections.py", line 1075, in read
    first_packet = self.connection._read_packet()
  File "C:\Users\sainikeshk\AppData\Local\Programs\Python\Python37\lib\site-packages\pymysql\connections.py", line 684, in _read_packet
    packet.check_error()
  File "C:\Users\sainikeshk\AppData\Local\Programs\Python\Python37\lib\site-packages\pymysql\protocol.py", line 220, in check_error
    err.raise_mysql_exception(self._data)
  File "C:\Users\sainikeshk\AppData\Local\Programs\Python\Python37\lib\site-packages\pymysql\err.py", line 109, in raise_mysql_exception
    raise errorclass(errno, errval)
pymysql.err.InternalError: (1054, "Unknown column 'ALBK' in 'field list'")
5804  2020-04-22 07:51:08,366 ERROR getSignals 1287 ::: error ::(1054, "Unknown column 'ALEMBICLTD' in 'field list'")
Traceback (most recent call last):
  File "D:\signals and decisions\bin\getSignals.py", line 1285, in getSignals
    cur.execute(isql)
  File "C:\Users\sainikeshk\AppData\Local\Programs\Python\Python37\lib\site-packages\pymysql\cursors.py", line 170, in execute
    result = self._query(query)
  File "C:\Users\sainikeshk\AppData\Local\Programs\Python\Python37\lib\site-packages\pymysql\cursors.py", line 328, in _query
    conn.query(q)
  File "C:\Users\sainikeshk\AppData\Local\Programs\Python\Python37\lib\site-packages\pymysql\connections.py", line 517, in query
    self._affected_rows = self._read_query_result(unbuffered=unbuffered)
  File "C:\Users\sainikeshk\AppData\Local\Programs\Python\Python37\lib\site-packages\pymysql\connections.py", line 732, in _read_query_result
    result.read()
  File "C:\Users\sainikeshk\AppData\Local\Programs\Python\Python37\lib\site-packages\pymysql\connections.py", line 1075, in read
    first_packet = self.connection._read_packet()
  File "C:\Users\sainikeshk\AppData\Local\Programs\Python\Python37\lib\site-packages\pymysql\connections.py", line 684, in _read_packet
    packet.check_error()
  File "C:\Users\sainikeshk\AppData\Local\Programs\Python\Python37\lib\site-packages\pymysql\protocol.py", line 220, in check_error
    err.raise_mysql_exception(self._data)
  File "C:\Users\sainikeshk\AppData\Local\Programs\Python\Python37\lib\site-packages\pymysql\err.py", line 109, in raise_mysql_exception
    raise errorclass(errno, errval)
pymysql.err.InternalError: (1054, "Unknown column 'ALEMBICLTD' in 'field list'")
5804  2020-04-22 07:51:10,549 ERROR getSignals 1287 ::: error ::(1054, "Unknown column 'ALICON' in 'field list'")
Traceback (most recent call last):
  File "D:\signals and decisions\bin\getSignals.py", line 1285, in getSignals
    cur.execute(isql)
  File "C:\Users\sainikeshk\AppData\Local\Programs\Python\Python37\lib\site-packages\pymysql\cursors.py", line 170, in execute
    result = self._query(query)
  File "C:\Users\sainikeshk\AppData\Local\Programs\Python\Python37\lib\site-packages\pymysql\cursors.py", line 328, in _query
    conn.query(q)
  File "C:\Users\sainikeshk\AppData\Local\Programs\Python\Python37\lib\site-packages\pymysql\connections.py", line 517, in query
    self._affected_rows = self._read_query_result(unbuffered=unbuffered)
  File "C:\Users\sainikeshk\AppData\Local\Programs\Python\Python37\lib\site-packages\pymysql\connections.py", line 732, in _read_query_result
    result.read()
  File "C:\Users\sainikeshk\AppData\Local\Programs\Python\Python37\lib\site-packages\pymysql\connections.py", line 1075, in read
    first_packet = self.connection._read_packet()
  File "C:\Users\sainikeshk\AppData\Local\Programs\Python\Python37\lib\site-packages\pymysql\connections.py", line 684, in _read_packet
    packet.check_error()
  File "C:\Users\sainikeshk\AppData\Local\Programs\Python\Python37\lib\site-packages\pymysql\protocol.py", line 220, in check_error
    err.raise_mysql_exception(self._data)
  File "C:\Users\sainikeshk\AppData\Local\Programs\Python\Python37\lib\site-packages\pymysql\err.py", line 109, in raise_mysql_exception
    raise errorclass(errno, errval)
pymysql.err.InternalError: (1054, "Unknown column 'ALICON' in 'field list'")
5804  2020-04-22 07:51:12,614 ERROR getSignals 1287 ::: error ::(1054, "Unknown column 'ALKALI' in 'field list'")
Traceback (most recent call last):
  File "D:\signals and decisions\bin\getSignals.py", line 1285, in getSignals
    cur.execute(isql)
  File "C:\Users\sainikeshk\AppData\Local\Programs\Python\Python37\lib\site-packages\pymysql\cursors.py", line 170, in execute
    result = self._query(query)
  File "C:\Users\sainikeshk\AppData\Local\Programs\Python\Python37\lib\site-packages\pymysql\cursors.py", line 328, in _query
    conn.query(q)
  File "C:\Users\sainikeshk\AppData\Local\Programs\Python\Python37\lib\site-packages\pymysql\connections.py", line 517, in query
    self._affected_rows = self._read_query_result(unbuffered=unbuffered)
  File "C:\Users\sainikeshk\AppData\Local\Programs\Python\Python37\lib\site-packages\pymysql\connections.py", line 732, in _read_query_result
    result.read()
  File "C:\Users\sainikeshk\AppData\Local\Programs\Python\Python37\lib\site-packages\pymysql\connections.py", line 1075, in read
    first_packet = self.connection._read_packet()
  File "C:\Users\sainikeshk\AppData\Local\Programs\Python\Python37\lib\site-packages\pymysql\connections.py", line 684, in _read_packet
    packet.check_error()
  File "C:\Users\sainikeshk\AppData\Local\Programs\Python\Python37\lib\site-packages\pymysql\protocol.py", line 220, in check_error
    err.raise_mysql_exception(self._data)
  File "C:\Users\sainikeshk\AppData\Local\Programs\Python\Python37\lib\site-packages\pymysql\err.py", line 109, in raise_mysql_exception
    raise errorclass(errno, errval)
pymysql.err.InternalError: (1054, "Unknown column 'ALKALI' in 'field list'")
5804  2020-04-22 07:51:14,960 ERROR getSignals 1287 ::: error ::(1054, "Unknown column 'ALKEM' in 'field list'")
Traceback (most recent call last):
  File "D:\signals and decisions\bin\getSignals.py", line 1285, in getSignals
    cur.execute(isql)
  File "C:\Users\sainikeshk\AppData\Local\Programs\Python\Python37\lib\site-packages\pymysql\cursors.py", line 170, in execute
    result = self._query(query)
  File "C:\Users\sainikeshk\AppData\Local\Programs\Python\Python37\lib\site-packages\pymysql\cursors.py", line 328, in _query
    conn.query(q)
  File "C:\Users\sainikeshk\AppData\Local\Programs\Python\Python37\lib\site-packages\pymysql\connections.py", line 517, in query
    self._affected_rows = self._read_query_result(unbuffered=unbuffered)
  File "C:\Users\sainikeshk\AppData\Local\Programs\Python\Python37\lib\site-packages\pymysql\connections.py", line 732, in _read_query_result
    result.read()
  File "C:\Users\sainikeshk\AppData\Local\Programs\Python\Python37\lib\site-packages\pymysql\connections.py", line 1075, in read
    first_packet = self.connection._read_packet()
  File "C:\Users\sainikeshk\AppData\Local\Programs\Python\Python37\lib\site-packages\pymysql\connections.py", line 684, in _read_packet
    packet.check_error()
  File "C:\Users\sainikeshk\AppData\Local\Programs\Python\Python37\lib\site-packages\pymysql\protocol.py", line 220, in check_error
    err.raise_mysql_exception(self._data)
  File "C:\Users\sainikeshk\AppData\Local\Programs\Python\Python37\lib\site-packages\pymysql\err.py", line 109, in raise_mysql_exception
    raise errorclass(errno, errval)
pymysql.err.InternalError: (1054, "Unknown column 'ALKEM' in 'field list'")
5804  2020-04-22 07:51:17,086 ERROR getSignals 1287 ::: error ::(1054, "Unknown column 'ALKYLAMINE' in 'field list'")
Traceback (most recent call last):
  File "D:\signals and decisions\bin\getSignals.py", line 1285, in getSignals
    cur.execute(isql)
  File "C:\Users\sainikeshk\AppData\Local\Programs\Python\Python37\lib\site-packages\pymysql\cursors.py", line 170, in execute
    result = self._query(query)
  File "C:\Users\sainikeshk\AppData\Local\Programs\Python\Python37\lib\site-packages\pymysql\cursors.py", line 328, in _query
    conn.query(q)
  File "C:\Users\sainikeshk\AppData\Local\Programs\Python\Python37\lib\site-packages\pymysql\connections.py", line 517, in query
    self._affected_rows = self._read_query_result(unbuffered=unbuffered)
  File "C:\Users\sainikeshk\AppData\Local\Programs\Python\Python37\lib\site-packages\pymysql\connections.py", line 732, in _read_query_result
    result.read()
  File "C:\Users\sainikeshk\AppData\Local\Programs\Python\Python37\lib\site-packages\pymysql\connections.py", line 1075, in read
    first_packet = self.connection._read_packet()
  File "C:\Users\sainikeshk\AppData\Local\Programs\Python\Python37\lib\site-packages\pymysql\connections.py", line 684, in _read_packet
    packet.check_error()
  File "C:\Users\sainikeshk\AppData\Local\Programs\Python\Python37\lib\site-packages\pymysql\protocol.py", line 220, in check_error
    err.raise_mysql_exception(self._data)
  File "C:\Users\sainikeshk\AppData\Local\Programs\Python\Python37\lib\site-packages\pymysql\err.py", line 109, in raise_mysql_exception
    raise errorclass(errno, errval)
pymysql.err.InternalError: (1054, "Unknown column 'ALKYLAMINE' in 'field list'")
5804  2020-04-22 07:51:19,525 ERROR getSignals 1287 ::: error ::(1054, "Unknown column 'ALLCARGO' in 'field list'")
Traceback (most recent call last):
  File "D:\signals and decisions\bin\getSignals.py", line 1285, in getSignals
    cur.execute(isql)
  File "C:\Users\sainikeshk\AppData\Local\Programs\Python\Python37\lib\site-packages\pymysql\cursors.py", line 170, in execute
    result = self._query(query)
  File "C:\Users\sainikeshk\AppData\Local\Programs\Python\Python37\lib\site-packages\pymysql\cursors.py", line 328, in _query
    conn.query(q)
  File "C:\Users\sainikeshk\AppData\Local\Programs\Python\Python37\lib\site-packages\pymysql\connections.py", line 517, in query
    self._affected_rows = self._read_query_result(unbuffered=unbuffered)
  File "C:\Users\sainikeshk\AppData\Local\Programs\Python\Python37\lib\site-packages\pymysql\connections.py", line 732, in _read_query_result
    result.read()
  File "C:\Users\sainikeshk\AppData\Local\Programs\Python\Python37\lib\site-packages\pymysql\connections.py", line 1075, in read
    first_packet = self.connection._read_packet()
  File "C:\Users\sainikeshk\AppData\Local\Programs\Python\Python37\lib\site-packages\pymysql\connections.py", line 684, in _read_packet
    packet.check_error()
  File "C:\Users\sainikeshk\AppData\Local\Programs\Python\Python37\lib\site-packages\pymysql\protocol.py", line 220, in check_error
    err.raise_mysql_exception(self._data)
  File "C:\Users\sainikeshk\AppData\Local\Programs\Python\Python37\lib\site-packages\pymysql\err.py", line 109, in raise_mysql_exception
    raise errorclass(errno, errval)
pymysql.err.InternalError: (1054, "Unknown column 'ALLCARGO' in 'field list'")
5804  2020-04-22 07:51:21,332 ERROR getSignals 1287 ::: error ::(1054, "Unknown column 'ALLSEC' in 'field list'")
Traceback (most recent call last):
  File "D:\signals and decisions\bin\getSignals.py", line 1285, in getSignals
    cur.execute(isql)
  File "C:\Users\sainikeshk\AppData\Local\Programs\Python\Python37\lib\site-packages\pymysql\cursors.py", line 170, in execute
    result = self._query(query)
  File "C:\Users\sainikeshk\AppData\Local\Programs\Python\Python37\lib\site-packages\pymysql\cursors.py", line 328, in _query
    conn.query(q)
  File "C:\Users\sainikeshk\AppData\Local\Programs\Python\Python37\lib\site-packages\pymysql\connections.py", line 517, in query
    self._affected_rows = self._read_query_result(unbuffered=unbuffered)
  File "C:\Users\sainikeshk\AppData\Local\Programs\Python\Python37\lib\site-packages\pymysql\connections.py", line 732, in _read_query_result
    result.read()
  File "C:\Users\sainikeshk\AppData\Local\Programs\Python\Python37\lib\site-packages\pymysql\connections.py", line 1075, in read
    first_packet = self.connection._read_packet()
  File "C:\Users\sainikeshk\AppData\Local\Programs\Python\Python37\lib\site-packages\pymysql\connections.py", line 684, in _read_packet
    packet.check_error()
  File "C:\Users\sainikeshk\AppData\Local\Programs\Python\Python37\lib\site-packages\pymysql\protocol.py", line 220, in check_error
    err.raise_mysql_exception(self._data)
  File "C:\Users\sainikeshk\AppData\Local\Programs\Python\Python37\lib\site-packages\pymysql\err.py", line 109, in raise_mysql_exception
    raise errorclass(errno, errval)
pymysql.err.InternalError: (1054, "Unknown column 'ALLSEC' in 'field list'")
5804  2020-04-22 07:51:23,377 ERROR getSignals 1287 ::: error ::(1054, "Unknown column 'ALMONDZ' in 'field list'")
Traceback (most recent call last):
  File "D:\signals and decisions\bin\getSignals.py", line 1285, in getSignals
    cur.execute(isql)
  File "C:\Users\sainikeshk\AppData\Local\Programs\Python\Python37\lib\site-packages\pymysql\cursors.py", line 170, in execute
    result = self._query(query)
  File "C:\Users\sainikeshk\AppData\Local\Programs\Python\Python37\lib\site-packages\pymysql\cursors.py", line 328, in _query
    conn.query(q)
  File "C:\Users\sainikeshk\AppData\Local\Programs\Python\Python37\lib\site-packages\pymysql\connections.py", line 517, in query
    self._affected_rows = self._read_query_result(unbuffered=unbuffered)
  File "C:\Users\sainikeshk\AppData\Local\Programs\Python\Python37\lib\site-packages\pymysql\connections.py", line 732, in _read_query_result
    result.read()
  File "C:\Users\sainikeshk\AppData\Local\Programs\Python\Python37\lib\site-packages\pymysql\connections.py", line 1075, in read
    first_packet = self.connection._read_packet()
  File "C:\Users\sainikeshk\AppData\Local\Programs\Python\Python37\lib\site-packages\pymysql\connections.py", line 684, in _read_packet
    packet.check_error()
  File "C:\Users\sainikeshk\AppData\Local\Programs\Python\Python37\lib\site-packages\pymysql\protocol.py", line 220, in check_error
    err.raise_mysql_exception(self._data)
  File "C:\Users\sainikeshk\AppData\Local\Programs\Python\Python37\lib\site-packages\pymysql\err.py", line 109, in raise_mysql_exception
    raise errorclass(errno, errval)
pymysql.err.InternalError: (1054, "Unknown column 'ALMONDZ' in 'field list'")
5804  2020-04-22 07:51:24,847 ERROR getSignals 1287 ::: error ::(1054, "Unknown column 'ALOKTEXT' in 'field list'")
Traceback (most recent call last):
  File "D:\signals and decisions\bin\getSignals.py", line 1285, in getSignals
    cur.execute(isql)
  File "C:\Users\sainikeshk\AppData\Local\Programs\Python\Python37\lib\site-packages\pymysql\cursors.py", line 170, in execute
    result = self._query(query)
  File "C:\Users\sainikeshk\AppData\Local\Programs\Python\Python37\lib\site-packages\pymysql\cursors.py", line 328, in _query
    conn.query(q)
  File "C:\Users\sainikeshk\AppData\Local\Programs\Python\Python37\lib\site-packages\pymysql\connections.py", line 517, in query
    self._affected_rows = self._read_query_result(unbuffered=unbuffered)
  File "C:\Users\sainikeshk\AppData\Local\Programs\Python\Python37\lib\site-packages\pymysql\connections.py", line 732, in _read_query_result
    result.read()
  File "C:\Users\sainikeshk\AppData\Local\Programs\Python\Python37\lib\site-packages\pymysql\connections.py", line 1075, in read
    first_packet = self.connection._read_packet()
  File "C:\Users\sainikeshk\AppData\Local\Programs\Python\Python37\lib\site-packages\pymysql\connections.py", line 684, in _read_packet
    packet.check_error()
  File "C:\Users\sainikeshk\AppData\Local\Programs\Python\Python37\lib\site-packages\pymysql\protocol.py", line 220, in check_error
    err.raise_mysql_exception(self._data)
  File "C:\Users\sainikeshk\AppData\Local\Programs\Python\Python37\lib\site-packages\pymysql\err.py", line 109, in raise_mysql_exception
    raise errorclass(errno, errval)
pymysql.err.InternalError: (1054, "Unknown column 'ALOKTEXT' in 'field list'")
5804  2020-04-22 07:51:27,087 ERROR getSignals 1287 ::: error ::(1054, "Unknown column 'ALPA' in 'field list'")
Traceback (most recent call last):
  File "D:\signals and decisions\bin\getSignals.py", line 1285, in getSignals
    cur.execute(isql)
  File "C:\Users\sainikeshk\AppData\Local\Programs\Python\Python37\lib\site-packages\pymysql\cursors.py", line 170, in execute
    result = self._query(query)
  File "C:\Users\sainikeshk\AppData\Local\Programs\Python\Python37\lib\site-packages\pymysql\cursors.py", line 328, in _query
    conn.query(q)
  File "C:\Users\sainikeshk\AppData\Local\Programs\Python\Python37\lib\site-packages\pymysql\connections.py", line 517, in query
    self._affected_rows = self._read_query_result(unbuffered=unbuffered)
  File "C:\Users\sainikeshk\AppData\Local\Programs\Python\Python37\lib\site-packages\pymysql\connections.py", line 732, in _read_query_result
    result.read()
  File "C:\Users\sainikeshk\AppData\Local\Programs\Python\Python37\lib\site-packages\pymysql\connections.py", line 1075, in read
    first_packet = self.connection._read_packet()
  File "C:\Users\sainikeshk\AppData\Local\Programs\Python\Python37\lib\site-packages\pymysql\connections.py", line 684, in _read_packet
    packet.check_error()
  File "C:\Users\sainikeshk\AppData\Local\Programs\Python\Python37\lib\site-packages\pymysql\protocol.py", line 220, in check_error
    err.raise_mysql_exception(self._data)
  File "C:\Users\sainikeshk\AppData\Local\Programs\Python\Python37\lib\site-packages\pymysql\err.py", line 109, in raise_mysql_exception
    raise errorclass(errno, errval)
pymysql.err.InternalError: (1054, "Unknown column 'ALPA' in 'field list'")
5804  2020-04-22 07:51:29,087 ERROR getSignals 1287 ::: error ::(1054, "Unknown column 'ALPHAGEO' in 'field list'")
Traceback (most recent call last):
  File "D:\signals and decisions\bin\getSignals.py", line 1285, in getSignals
    cur.execute(isql)
  File "C:\Users\sainikeshk\AppData\Local\Programs\Python\Python37\lib\site-packages\pymysql\cursors.py", line 170, in execute
    result = self._query(query)
  File "C:\Users\sainikeshk\AppData\Local\Programs\Python\Python37\lib\site-packages\pymysql\cursors.py", line 328, in _query
    conn.query(q)
  File "C:\Users\sainikeshk\AppData\Local\Programs\Python\Python37\lib\site-packages\pymysql\connections.py", line 517, in query
    self._affected_rows = self._read_query_result(unbuffered=unbuffered)
  File "C:\Users\sainikeshk\AppData\Local\Programs\Python\Python37\lib\site-packages\pymysql\connections.py", line 732, in _read_query_result
    result.read()
  File "C:\Users\sainikeshk\AppData\Local\Programs\Python\Python37\lib\site-packages\pymysql\connections.py", line 1075, in read
    first_packet = self.connection._read_packet()
  File "C:\Users\sainikeshk\AppData\Local\Programs\Python\Python37\lib\site-packages\pymysql\connections.py", line 684, in _read_packet
    packet.check_error()
  File "C:\Users\sainikeshk\AppData\Local\Programs\Python\Python37\lib\site-packages\pymysql\protocol.py", line 220, in check_error
    err.raise_mysql_exception(self._data)
  File "C:\Users\sainikeshk\AppData\Local\Programs\Python\Python37\lib\site-packages\pymysql\err.py", line 109, in raise_mysql_exception
    raise errorclass(errno, errval)
pymysql.err.InternalError: (1054, "Unknown column 'ALPHAGEO' in 'field list'")
5804  2020-04-22 07:51:32,042 ERROR getSignals 1287 ::: error ::(1054, "Unknown column 'AMARAJABAT' in 'field list'")
Traceback (most recent call last):
  File "D:\signals and decisions\bin\getSignals.py", line 1285, in getSignals
    cur.execute(isql)
  File "C:\Users\sainikeshk\AppData\Local\Programs\Python\Python37\lib\site-packages\pymysql\cursors.py", line 170, in execute
    result = self._query(query)
  File "C:\Users\sainikeshk\AppData\Local\Programs\Python\Python37\lib\site-packages\pymysql\cursors.py", line 328, in _query
    conn.query(q)
  File "C:\Users\sainikeshk\AppData\Local\Programs\Python\Python37\lib\site-packages\pymysql\connections.py", line 517, in query
    self._affected_rows = self._read_query_result(unbuffered=unbuffered)
  File "C:\Users\sainikeshk\AppData\Local\Programs\Python\Python37\lib\site-packages\pymysql\connections.py", line 732, in _read_query_result
    result.read()
  File "C:\Users\sainikeshk\AppData\Local\Programs\Python\Python37\lib\site-packages\pymysql\connections.py", line 1075, in read
    first_packet = self.connection._read_packet()
  File "C:\Users\sainikeshk\AppData\Local\Programs\Python\Python37\lib\site-packages\pymysql\connections.py", line 684, in _read_packet
    packet.check_error()
  File "C:\Users\sainikeshk\AppData\Local\Programs\Python\Python37\lib\site-packages\pymysql\protocol.py", line 220, in check_error
    err.raise_mysql_exception(self._data)
  File "C:\Users\sainikeshk\AppData\Local\Programs\Python\Python37\lib\site-packages\pymysql\err.py", line 109, in raise_mysql_exception
    raise errorclass(errno, errval)
pymysql.err.InternalError: (1054, "Unknown column 'AMARAJABAT' in 'field list'")
5804  2020-04-22 07:51:34,051 ERROR getSignals 1287 ::: error ::(1054, "Unknown column 'AMBER' in 'field list'")
Traceback (most recent call last):
  File "D:\signals and decisions\bin\getSignals.py", line 1285, in getSignals
    cur.execute(isql)
  File "C:\Users\sainikeshk\AppData\Local\Programs\Python\Python37\lib\site-packages\pymysql\cursors.py", line 170, in execute
    result = self._query(query)
  File "C:\Users\sainikeshk\AppData\Local\Programs\Python\Python37\lib\site-packages\pymysql\cursors.py", line 328, in _query
    conn.query(q)
  File "C:\Users\sainikeshk\AppData\Local\Programs\Python\Python37\lib\site-packages\pymysql\connections.py", line 517, in query
    self._affected_rows = self._read_query_result(unbuffered=unbuffered)
  File "C:\Users\sainikeshk\AppData\Local\Programs\Python\Python37\lib\site-packages\pymysql\connections.py", line 732, in _read_query_result
    result.read()
  File "C:\Users\sainikeshk\AppData\Local\Programs\Python\Python37\lib\site-packages\pymysql\connections.py", line 1075, in read
    first_packet = self.connection._read_packet()
  File "C:\Users\sainikeshk\AppData\Local\Programs\Python\Python37\lib\site-packages\pymysql\connections.py", line 684, in _read_packet
    packet.check_error()
  File "C:\Users\sainikeshk\AppData\Local\Programs\Python\Python37\lib\site-packages\pymysql\protocol.py", line 220, in check_error
    err.raise_mysql_exception(self._data)
  File "C:\Users\sainikeshk\AppData\Local\Programs\Python\Python37\lib\site-packages\pymysql\err.py", line 109, in raise_mysql_exception
    raise errorclass(errno, errval)
pymysql.err.InternalError: (1054, "Unknown column 'AMBER' in 'field list'")
5804  2020-04-22 07:51:36,674 ERROR getSignals 1287 ::: error ::(1054, "Unknown column 'AMBIKCO' in 'field list'")
Traceback (most recent call last):
  File "D:\signals and decisions\bin\getSignals.py", line 1285, in getSignals
    cur.execute(isql)
  File "C:\Users\sainikeshk\AppData\Local\Programs\Python\Python37\lib\site-packages\pymysql\cursors.py", line 170, in execute
    result = self._query(query)
  File "C:\Users\sainikeshk\AppData\Local\Programs\Python\Python37\lib\site-packages\pymysql\cursors.py", line 328, in _query
    conn.query(q)
  File "C:\Users\sainikeshk\AppData\Local\Programs\Python\Python37\lib\site-packages\pymysql\connections.py", line 517, in query
    self._affected_rows = self._read_query_result(unbuffered=unbuffered)
  File "C:\Users\sainikeshk\AppData\Local\Programs\Python\Python37\lib\site-packages\pymysql\connections.py", line 732, in _read_query_result
    result.read()
  File "C:\Users\sainikeshk\AppData\Local\Programs\Python\Python37\lib\site-packages\pymysql\connections.py", line 1075, in read
    first_packet = self.connection._read_packet()
  File "C:\Users\sainikeshk\AppData\Local\Programs\Python\Python37\lib\site-packages\pymysql\connections.py", line 684, in _read_packet
    packet.check_error()
  File "C:\Users\sainikeshk\AppData\Local\Programs\Python\Python37\lib\site-packages\pymysql\protocol.py", line 220, in check_error
    err.raise_mysql_exception(self._data)
  File "C:\Users\sainikeshk\AppData\Local\Programs\Python\Python37\lib\site-packages\pymysql\err.py", line 109, in raise_mysql_exception
    raise errorclass(errno, errval)
pymysql.err.InternalError: (1054, "Unknown column 'AMBIKCO' in 'field list'")
5804  2020-04-22 07:51:38,726 ERROR getSignals 1287 ::: error ::(1054, "Unknown column 'AMBUJACEM' in 'field list'")
Traceback (most recent call last):
  File "D:\signals and decisions\bin\getSignals.py", line 1285, in getSignals
    cur.execute(isql)
  File "C:\Users\sainikeshk\AppData\Local\Programs\Python\Python37\lib\site-packages\pymysql\cursors.py", line 170, in execute
    result = self._query(query)
  File "C:\Users\sainikeshk\AppData\Local\Programs\Python\Python37\lib\site-packages\pymysql\cursors.py", line 328, in _query
    conn.query(q)
  File "C:\Users\sainikeshk\AppData\Local\Programs\Python\Python37\lib\site-packages\pymysql\connections.py", line 517, in query
    self._affected_rows = self._read_query_result(unbuffered=unbuffered)
  File "C:\Users\sainikeshk\AppData\Local\Programs\Python\Python37\lib\site-packages\pymysql\connections.py", line 732, in _read_query_result
    result.read()
  File "C:\Users\sainikeshk\AppData\Local\Programs\Python\Python37\lib\site-packages\pymysql\connections.py", line 1075, in read
    first_packet = self.connection._read_packet()
  File "C:\Users\sainikeshk\AppData\Local\Programs\Python\Python37\lib\site-packages\pymysql\connections.py", line 684, in _read_packet
    packet.check_error()
  File "C:\Users\sainikeshk\AppData\Local\Programs\Python\Python37\lib\site-packages\pymysql\protocol.py", line 220, in check_error
    err.raise_mysql_exception(self._data)
  File "C:\Users\sainikeshk\AppData\Local\Programs\Python\Python37\lib\site-packages\pymysql\err.py", line 109, in raise_mysql_exception
    raise errorclass(errno, errval)
pymysql.err.InternalError: (1054, "Unknown column 'AMBUJACEM' in 'field list'")
5804  2020-04-22 07:51:41,127 ERROR getSignals 1287 ::: error ::(1054, "Unknown column 'AMDIND' in 'field list'")
Traceback (most recent call last):
  File "D:\signals and decisions\bin\getSignals.py", line 1285, in getSignals
    cur.execute(isql)
  File "C:\Users\sainikeshk\AppData\Local\Programs\Python\Python37\lib\site-packages\pymysql\cursors.py", line 170, in execute
    result = self._query(query)
  File "C:\Users\sainikeshk\AppData\Local\Programs\Python\Python37\lib\site-packages\pymysql\cursors.py", line 328, in _query
    conn.query(q)
  File "C:\Users\sainikeshk\AppData\Local\Programs\Python\Python37\lib\site-packages\pymysql\connections.py", line 517, in query
    self._affected_rows = self._read_query_result(unbuffered=unbuffered)
  File "C:\Users\sainikeshk\AppData\Local\Programs\Python\Python37\lib\site-packages\pymysql\connections.py", line 732, in _read_query_result
    result.read()
  File "C:\Users\sainikeshk\AppData\Local\Programs\Python\Python37\lib\site-packages\pymysql\connections.py", line 1075, in read
    first_packet = self.connection._read_packet()
  File "C:\Users\sainikeshk\AppData\Local\Programs\Python\Python37\lib\site-packages\pymysql\connections.py", line 684, in _read_packet
    packet.check_error()
  File "C:\Users\sainikeshk\AppData\Local\Programs\Python\Python37\lib\site-packages\pymysql\protocol.py", line 220, in check_error
    err.raise_mysql_exception(self._data)
  File "C:\Users\sainikeshk\AppData\Local\Programs\Python\Python37\lib\site-packages\pymysql\err.py", line 109, in raise_mysql_exception
    raise errorclass(errno, errval)
pymysql.err.InternalError: (1054, "Unknown column 'AMDIND' in 'field list'")
5804  2020-04-22 07:51:43,203 ERROR getSignals 1287 ::: error ::(1054, "Unknown column 'AMJLAND' in 'field list'")
Traceback (most recent call last):
  File "D:\signals and decisions\bin\getSignals.py", line 1285, in getSignals
    cur.execute(isql)
  File "C:\Users\sainikeshk\AppData\Local\Programs\Python\Python37\lib\site-packages\pymysql\cursors.py", line 170, in execute
    result = self._query(query)
  File "C:\Users\sainikeshk\AppData\Local\Programs\Python\Python37\lib\site-packages\pymysql\cursors.py", line 328, in _query
    conn.query(q)
  File "C:\Users\sainikeshk\AppData\Local\Programs\Python\Python37\lib\site-packages\pymysql\connections.py", line 517, in query
    self._affected_rows = self._read_query_result(unbuffered=unbuffered)
  File "C:\Users\sainikeshk\AppData\Local\Programs\Python\Python37\lib\site-packages\pymysql\connections.py", line 732, in _read_query_result
    result.read()
  File "C:\Users\sainikeshk\AppData\Local\Programs\Python\Python37\lib\site-packages\pymysql\connections.py", line 1075, in read
    first_packet = self.connection._read_packet()
  File "C:\Users\sainikeshk\AppData\Local\Programs\Python\Python37\lib\site-packages\pymysql\connections.py", line 684, in _read_packet
    packet.check_error()
  File "C:\Users\sainikeshk\AppData\Local\Programs\Python\Python37\lib\site-packages\pymysql\protocol.py", line 220, in check_error
    err.raise_mysql_exception(self._data)
  File "C:\Users\sainikeshk\AppData\Local\Programs\Python\Python37\lib\site-packages\pymysql\err.py", line 109, in raise_mysql_exception
    raise errorclass(errno, errval)
pymysql.err.InternalError: (1054, "Unknown column 'AMJLAND' in 'field list'")
5804  2020-04-22 07:51:45,343 ERROR getSignals 1287 ::: error ::(1054, "Unknown column 'AMRUTANJAN' in 'field list'")
Traceback (most recent call last):
  File "D:\signals and decisions\bin\getSignals.py", line 1285, in getSignals
    cur.execute(isql)
  File "C:\Users\sainikeshk\AppData\Local\Programs\Python\Python37\lib\site-packages\pymysql\cursors.py", line 170, in execute
    result = self._query(query)
  File "C:\Users\sainikeshk\AppData\Local\Programs\Python\Python37\lib\site-packages\pymysql\cursors.py", line 328, in _query
    conn.query(q)
  File "C:\Users\sainikeshk\AppData\Local\Programs\Python\Python37\lib\site-packages\pymysql\connections.py", line 517, in query
    self._affected_rows = self._read_query_result(unbuffered=unbuffered)
  File "C:\Users\sainikeshk\AppData\Local\Programs\Python\Python37\lib\site-packages\pymysql\connections.py", line 732, in _read_query_result
    result.read()
  File "C:\Users\sainikeshk\AppData\Local\Programs\Python\Python37\lib\site-packages\pymysql\connections.py", line 1075, in read
    first_packet = self.connection._read_packet()
  File "C:\Users\sainikeshk\AppData\Local\Programs\Python\Python37\lib\site-packages\pymysql\connections.py", line 684, in _read_packet
    packet.check_error()
  File "C:\Users\sainikeshk\AppData\Local\Programs\Python\Python37\lib\site-packages\pymysql\protocol.py", line 220, in check_error
    err.raise_mysql_exception(self._data)
  File "C:\Users\sainikeshk\AppData\Local\Programs\Python\Python37\lib\site-packages\pymysql\err.py", line 109, in raise_mysql_exception
    raise errorclass(errno, errval)
pymysql.err.InternalError: (1054, "Unknown column 'AMRUTANJAN' in 'field list'")
5804  2020-04-22 07:51:47,768 ERROR getSignals 1287 ::: error ::(1054, "Unknown column 'ANANTRAJ' in 'field list'")
Traceback (most recent call last):
  File "D:\signals and decisions\bin\getSignals.py", line 1285, in getSignals
    cur.execute(isql)
  File "C:\Users\sainikeshk\AppData\Local\Programs\Python\Python37\lib\site-packages\pymysql\cursors.py", line 170, in execute
    result = self._query(query)
  File "C:\Users\sainikeshk\AppData\Local\Programs\Python\Python37\lib\site-packages\pymysql\cursors.py", line 328, in _query
    conn.query(q)
  File "C:\Users\sainikeshk\AppData\Local\Programs\Python\Python37\lib\site-packages\pymysql\connections.py", line 517, in query
    self._affected_rows = self._read_query_result(unbuffered=unbuffered)
  File "C:\Users\sainikeshk\AppData\Local\Programs\Python\Python37\lib\site-packages\pymysql\connections.py", line 732, in _read_query_result
    result.read()
  File "C:\Users\sainikeshk\AppData\Local\Programs\Python\Python37\lib\site-packages\pymysql\connections.py", line 1075, in read
    first_packet = self.connection._read_packet()
  File "C:\Users\sainikeshk\AppData\Local\Programs\Python\Python37\lib\site-packages\pymysql\connections.py", line 684, in _read_packet
    packet.check_error()
  File "C:\Users\sainikeshk\AppData\Local\Programs\Python\Python37\lib\site-packages\pymysql\protocol.py", line 220, in check_error
    err.raise_mysql_exception(self._data)
  File "C:\Users\sainikeshk\AppData\Local\Programs\Python\Python37\lib\site-packages\pymysql\err.py", line 109, in raise_mysql_exception
    raise errorclass(errno, errval)
pymysql.err.InternalError: (1054, "Unknown column 'ANANTRAJ' in 'field list'")
5804  2020-04-22 07:51:49,795 ERROR getSignals 1287 ::: error ::(1054, "Unknown column 'ANDHRABANK' in 'field list'")
Traceback (most recent call last):
  File "D:\signals and decisions\bin\getSignals.py", line 1285, in getSignals
    cur.execute(isql)
  File "C:\Users\sainikeshk\AppData\Local\Programs\Python\Python37\lib\site-packages\pymysql\cursors.py", line 170, in execute
    result = self._query(query)
  File "C:\Users\sainikeshk\AppData\Local\Programs\Python\Python37\lib\site-packages\pymysql\cursors.py", line 328, in _query
    conn.query(q)
  File "C:\Users\sainikeshk\AppData\Local\Programs\Python\Python37\lib\site-packages\pymysql\connections.py", line 517, in query
    self._affected_rows = self._read_query_result(unbuffered=unbuffered)
  File "C:\Users\sainikeshk\AppData\Local\Programs\Python\Python37\lib\site-packages\pymysql\connections.py", line 732, in _read_query_result
    result.read()
  File "C:\Users\sainikeshk\AppData\Local\Programs\Python\Python37\lib\site-packages\pymysql\connections.py", line 1075, in read
    first_packet = self.connection._read_packet()
  File "C:\Users\sainikeshk\AppData\Local\Programs\Python\Python37\lib\site-packages\pymysql\connections.py", line 684, in _read_packet
    packet.check_error()
  File "C:\Users\sainikeshk\AppData\Local\Programs\Python\Python37\lib\site-packages\pymysql\protocol.py", line 220, in check_error
    err.raise_mysql_exception(self._data)
  File "C:\Users\sainikeshk\AppData\Local\Programs\Python\Python37\lib\site-packages\pymysql\err.py", line 109, in raise_mysql_exception
    raise errorclass(errno, errval)
pymysql.err.InternalError: (1054, "Unknown column 'ANDHRABANK' in 'field list'")
5804  2020-04-22 07:51:51,284 ERROR getSignals 1287 ::: error ::(1054, "Unknown column 'ANDHRACEMT' in 'field list'")
Traceback (most recent call last):
  File "D:\signals and decisions\bin\getSignals.py", line 1285, in getSignals
    cur.execute(isql)
  File "C:\Users\sainikeshk\AppData\Local\Programs\Python\Python37\lib\site-packages\pymysql\cursors.py", line 170, in execute
    result = self._query(query)
  File "C:\Users\sainikeshk\AppData\Local\Programs\Python\Python37\lib\site-packages\pymysql\cursors.py", line 328, in _query
    conn.query(q)
  File "C:\Users\sainikeshk\AppData\Local\Programs\Python\Python37\lib\site-packages\pymysql\connections.py", line 517, in query
    self._affected_rows = self._read_query_result(unbuffered=unbuffered)
  File "C:\Users\sainikeshk\AppData\Local\Programs\Python\Python37\lib\site-packages\pymysql\connections.py", line 732, in _read_query_result
    result.read()
  File "C:\Users\sainikeshk\AppData\Local\Programs\Python\Python37\lib\site-packages\pymysql\connections.py", line 1075, in read
    first_packet = self.connection._read_packet()
  File "C:\Users\sainikeshk\AppData\Local\Programs\Python\Python37\lib\site-packages\pymysql\connections.py", line 684, in _read_packet
    packet.check_error()
  File "C:\Users\sainikeshk\AppData\Local\Programs\Python\Python37\lib\site-packages\pymysql\protocol.py", line 220, in check_error
    err.raise_mysql_exception(self._data)
  File "C:\Users\sainikeshk\AppData\Local\Programs\Python\Python37\lib\site-packages\pymysql\err.py", line 109, in raise_mysql_exception
    raise errorclass(errno, errval)
pymysql.err.InternalError: (1054, "Unknown column 'ANDHRACEMT' in 'field list'")
5804  2020-04-22 07:51:53,659 ERROR getSignals 1287 ::: error ::(1054, "Unknown column 'ANDHRSUGAR' in 'field list'")
Traceback (most recent call last):
  File "D:\signals and decisions\bin\getSignals.py", line 1285, in getSignals
    cur.execute(isql)
  File "C:\Users\sainikeshk\AppData\Local\Programs\Python\Python37\lib\site-packages\pymysql\cursors.py", line 170, in execute
    result = self._query(query)
  File "C:\Users\sainikeshk\AppData\Local\Programs\Python\Python37\lib\site-packages\pymysql\cursors.py", line 328, in _query
    conn.query(q)
  File "C:\Users\sainikeshk\AppData\Local\Programs\Python\Python37\lib\site-packages\pymysql\connections.py", line 517, in query
    self._affected_rows = self._read_query_result(unbuffered=unbuffered)
  File "C:\Users\sainikeshk\AppData\Local\Programs\Python\Python37\lib\site-packages\pymysql\connections.py", line 732, in _read_query_result
    result.read()
  File "C:\Users\sainikeshk\AppData\Local\Programs\Python\Python37\lib\site-packages\pymysql\connections.py", line 1075, in read
    first_packet = self.connection._read_packet()
  File "C:\Users\sainikeshk\AppData\Local\Programs\Python\Python37\lib\site-packages\pymysql\connections.py", line 684, in _read_packet
    packet.check_error()
  File "C:\Users\sainikeshk\AppData\Local\Programs\Python\Python37\lib\site-packages\pymysql\protocol.py", line 220, in check_error
    err.raise_mysql_exception(self._data)
  File "C:\Users\sainikeshk\AppData\Local\Programs\Python\Python37\lib\site-packages\pymysql\err.py", line 109, in raise_mysql_exception
    raise errorclass(errno, errval)
pymysql.err.InternalError: (1054, "Unknown column 'ANDHRSUGAR' in 'field list'")
5804  2020-04-22 07:51:55,518 ERROR getSignals 1287 ::: error ::(1054, "Unknown column 'ANIKINDS' in 'field list'")
Traceback (most recent call last):
  File "D:\signals and decisions\bin\getSignals.py", line 1285, in getSignals
    cur.execute(isql)
  File "C:\Users\sainikeshk\AppData\Local\Programs\Python\Python37\lib\site-packages\pymysql\cursors.py", line 170, in execute
    result = self._query(query)
  File "C:\Users\sainikeshk\AppData\Local\Programs\Python\Python37\lib\site-packages\pymysql\cursors.py", line 328, in _query
    conn.query(q)
  File "C:\Users\sainikeshk\AppData\Local\Programs\Python\Python37\lib\site-packages\pymysql\connections.py", line 517, in query
    self._affected_rows = self._read_query_result(unbuffered=unbuffered)
  File "C:\Users\sainikeshk\AppData\Local\Programs\Python\Python37\lib\site-packages\pymysql\connections.py", line 732, in _read_query_result
    result.read()
  File "C:\Users\sainikeshk\AppData\Local\Programs\Python\Python37\lib\site-packages\pymysql\connections.py", line 1075, in read
    first_packet = self.connection._read_packet()
  File "C:\Users\sainikeshk\AppData\Local\Programs\Python\Python37\lib\site-packages\pymysql\connections.py", line 684, in _read_packet
    packet.check_error()
  File "C:\Users\sainikeshk\AppData\Local\Programs\Python\Python37\lib\site-packages\pymysql\protocol.py", line 220, in check_error
    err.raise_mysql_exception(self._data)
  File "C:\Users\sainikeshk\AppData\Local\Programs\Python\Python37\lib\site-packages\pymysql\err.py", line 109, in raise_mysql_exception
    raise errorclass(errno, errval)
pymysql.err.InternalError: (1054, "Unknown column 'ANIKINDS' in 'field list'")
5804  2020-04-22 07:51:56,284 ERROR getSignals 1287 ::: error ::(1054, "Unknown column 'ANKITMETAL' in 'field list'")
Traceback (most recent call last):
  File "D:\signals and decisions\bin\getSignals.py", line 1285, in getSignals
    cur.execute(isql)
  File "C:\Users\sainikeshk\AppData\Local\Programs\Python\Python37\lib\site-packages\pymysql\cursors.py", line 170, in execute
    result = self._query(query)
  File "C:\Users\sainikeshk\AppData\Local\Programs\Python\Python37\lib\site-packages\pymysql\cursors.py", line 328, in _query
    conn.query(q)
  File "C:\Users\sainikeshk\AppData\Local\Programs\Python\Python37\lib\site-packages\pymysql\connections.py", line 517, in query
    self._affected_rows = self._read_query_result(unbuffered=unbuffered)
  File "C:\Users\sainikeshk\AppData\Local\Programs\Python\Python37\lib\site-packages\pymysql\connections.py", line 732, in _read_query_result
    result.read()
  File "C:\Users\sainikeshk\AppData\Local\Programs\Python\Python37\lib\site-packages\pymysql\connections.py", line 1075, in read
    first_packet = self.connection._read_packet()
  File "C:\Users\sainikeshk\AppData\Local\Programs\Python\Python37\lib\site-packages\pymysql\connections.py", line 684, in _read_packet
    packet.check_error()
  File "C:\Users\sainikeshk\AppData\Local\Programs\Python\Python37\lib\site-packages\pymysql\protocol.py", line 220, in check_error
    err.raise_mysql_exception(self._data)
  File "C:\Users\sainikeshk\AppData\Local\Programs\Python\Python37\lib\site-packages\pymysql\err.py", line 109, in raise_mysql_exception
    raise errorclass(errno, errval)
pymysql.err.InternalError: (1054, "Unknown column 'ANKITMETAL' in 'field list'")
5804  2020-04-22 07:51:58,695 ERROR getSignals 1287 ::: error ::(1054, "Unknown column 'ANSALAPI' in 'field list'")
Traceback (most recent call last):
  File "D:\signals and decisions\bin\getSignals.py", line 1285, in getSignals
    cur.execute(isql)
  File "C:\Users\sainikeshk\AppData\Local\Programs\Python\Python37\lib\site-packages\pymysql\cursors.py", line 170, in execute
    result = self._query(query)
  File "C:\Users\sainikeshk\AppData\Local\Programs\Python\Python37\lib\site-packages\pymysql\cursors.py", line 328, in _query
    conn.query(q)
  File "C:\Users\sainikeshk\AppData\Local\Programs\Python\Python37\lib\site-packages\pymysql\connections.py", line 517, in query
    self._affected_rows = self._read_query_result(unbuffered=unbuffered)
  File "C:\Users\sainikeshk\AppData\Local\Programs\Python\Python37\lib\site-packages\pymysql\connections.py", line 732, in _read_query_result
    result.read()
  File "C:\Users\sainikeshk\AppData\Local\Programs\Python\Python37\lib\site-packages\pymysql\connections.py", line 1075, in read
    first_packet = self.connection._read_packet()
  File "C:\Users\sainikeshk\AppData\Local\Programs\Python\Python37\lib\site-packages\pymysql\connections.py", line 684, in _read_packet
    packet.check_error()
  File "C:\Users\sainikeshk\AppData\Local\Programs\Python\Python37\lib\site-packages\pymysql\protocol.py", line 220, in check_error
    err.raise_mysql_exception(self._data)
  File "C:\Users\sainikeshk\AppData\Local\Programs\Python\Python37\lib\site-packages\pymysql\err.py", line 109, in raise_mysql_exception
    raise errorclass(errno, errval)
pymysql.err.InternalError: (1054, "Unknown column 'ANSALAPI' in 'field list'")
5804  2020-04-22 07:52:00,345 ERROR getSignals 1287 ::: error ::(1054, "Unknown column 'ANSALHSG' in 'field list'")
Traceback (most recent call last):
  File "D:\signals and decisions\bin\getSignals.py", line 1285, in getSignals
    cur.execute(isql)
  File "C:\Users\sainikeshk\AppData\Local\Programs\Python\Python37\lib\site-packages\pymysql\cursors.py", line 170, in execute
    result = self._query(query)
  File "C:\Users\sainikeshk\AppData\Local\Programs\Python\Python37\lib\site-packages\pymysql\cursors.py", line 328, in _query
    conn.query(q)
  File "C:\Users\sainikeshk\AppData\Local\Programs\Python\Python37\lib\site-packages\pymysql\connections.py", line 517, in query
    self._affected_rows = self._read_query_result(unbuffered=unbuffered)
  File "C:\Users\sainikeshk\AppData\Local\Programs\Python\Python37\lib\site-packages\pymysql\connections.py", line 732, in _read_query_result
    result.read()
  File "C:\Users\sainikeshk\AppData\Local\Programs\Python\Python37\lib\site-packages\pymysql\connections.py", line 1075, in read
    first_packet = self.connection._read_packet()
  File "C:\Users\sainikeshk\AppData\Local\Programs\Python\Python37\lib\site-packages\pymysql\connections.py", line 684, in _read_packet
    packet.check_error()
  File "C:\Users\sainikeshk\AppData\Local\Programs\Python\Python37\lib\site-packages\pymysql\protocol.py", line 220, in check_error
    err.raise_mysql_exception(self._data)
  File "C:\Users\sainikeshk\AppData\Local\Programs\Python\Python37\lib\site-packages\pymysql\err.py", line 109, in raise_mysql_exception
    raise errorclass(errno, errval)
pymysql.err.InternalError: (1054, "Unknown column 'ANSALHSG' in 'field list'")
5804  2020-04-22 07:52:03,126 ERROR getSignals 1287 ::: error ::(1054, "Unknown column 'ANUP' in 'field list'")
Traceback (most recent call last):
  File "D:\signals and decisions\bin\getSignals.py", line 1285, in getSignals
    cur.execute(isql)
  File "C:\Users\sainikeshk\AppData\Local\Programs\Python\Python37\lib\site-packages\pymysql\cursors.py", line 170, in execute
    result = self._query(query)
  File "C:\Users\sainikeshk\AppData\Local\Programs\Python\Python37\lib\site-packages\pymysql\cursors.py", line 328, in _query
    conn.query(q)
  File "C:\Users\sainikeshk\AppData\Local\Programs\Python\Python37\lib\site-packages\pymysql\connections.py", line 517, in query
    self._affected_rows = self._read_query_result(unbuffered=unbuffered)
  File "C:\Users\sainikeshk\AppData\Local\Programs\Python\Python37\lib\site-packages\pymysql\connections.py", line 732, in _read_query_result
    result.read()
  File "C:\Users\sainikeshk\AppData\Local\Programs\Python\Python37\lib\site-packages\pymysql\connections.py", line 1075, in read
    first_packet = self.connection._read_packet()
  File "C:\Users\sainikeshk\AppData\Local\Programs\Python\Python37\lib\site-packages\pymysql\connections.py", line 684, in _read_packet
    packet.check_error()
  File "C:\Users\sainikeshk\AppData\Local\Programs\Python\Python37\lib\site-packages\pymysql\protocol.py", line 220, in check_error
    err.raise_mysql_exception(self._data)
  File "C:\Users\sainikeshk\AppData\Local\Programs\Python\Python37\lib\site-packages\pymysql\err.py", line 109, in raise_mysql_exception
    raise errorclass(errno, errval)
pymysql.err.InternalError: (1054, "Unknown column 'ANUP' in 'field list'")
